
#######################################################################
# +-----------------------------------------------------------------+ #
# |                            BO3 object                           | #
# +-----------------------------------------------------------------+ #
#######################################################################

# This is the config file of a custom object.
# If you add this object correctly to your BiomeConfigs, it will spawn in the world.

# This is the creator of this BO3 object
Author: EmptyStar

# A short description of this BO3 object
Description: No description given

# The BO3 version, don't change this! It can be used by external applications to do a version check.
Version: 3

# The settings mode, WriteAll, WriteWithoutComments or WriteDisable. See WorldConfig.
SettingsMode: WriteDisable


#######################################################################
# +-----------------------------------------------------------------+ #
# |                          Main settings                          | #
# +-----------------------------------------------------------------+ #
#######################################################################

# This needs to be set to true to spawn the object in the Tree and Sapling resources.
Tree: false

# The frequency of the BO3 from 1 to 200. Tries this many times to spawn this BO3 when using the CustomObject(...) resource.
# Ignored by Tree(..), Sapling(..) and CustomStructure(..)
Frequency: 1

# The rarity of the BO3 from 0 to 100. Each spawn attempt has rarity% chance to succeed when using the CustomObject(...) resource.
# Ignored by Tree(..), Sapling(..) and CustomStructure(..)
Rarity: 0.125

# If you set this to true, the BO3 will be placed with a random rotation.
RotateRandomly: true

# The spawn height of the BO3 - randomY, highestBlock or highestSolidBlock.
SpawnHeight: randomY

# The offset from the spawn height to spawn this BO3
# Ex. SpawnHeight = highestSolidBlock, SpawnHeightOffset = 3; This object will spawn 3 blocks above the highest solid block
SpawnHeightOffset: 0

# A random amount to offset the spawn location from the spawn offset height
# Ex. SpawnHeightOffset = 3, SpawnHeightVariance = 3; This object will spawn 3 to 6 blocks above the original spot it would have spawned
SpawnHeightVariance: 0

######################
# Extrusion settings #
######################

# The style of extrusion you wish to use - BottomDown, TopUp, None (Default)
ExtrudeMode: None

# The blocks to extrude your BO3 through
ExtrudeThroughBlocks: AIR

# The height limits for the BO3.
MinHeight: 0

MaxHeight: 255

# Objects can have other objects attacthed to it: branches. Branches can also
# have branches attached to it, which can also have branches, etc. This is the
# maximum branch depth for this objects.
MaxBranchDepth: 1024

# When spawned with the UseWorld keyword, this BO3 should NOT spawn in the following biomes.
# If you writer.write the BO3 name directly in the BiomeConfigs, this will be ignored.
ExcludedBiomes: All


#######################################################################
# +-----------------------------------------------------------------+ #
# |                      Source block settings                      | #
# +-----------------------------------------------------------------+ #
#######################################################################

# The block(s) the BO3 should spawn in.
SourceBlocks: AIR

# The maximum percentage of the BO3 that can be outside the SourceBlock.
# The BO3 won't be placed on a location with more blocks outside the SourceBlock than this percentage.
MaxPercentageOutsideSourceBlock: 20

# What to do when a block is about to be placed outside the SourceBlock? (dontPlace, placeAnyway)
OutsideSourceBlock: placeAnyway


#######################################################################
# +-----------------------------------------------------------------+ #
# |                              Blocks                             | #
# +-----------------------------------------------------------------+ #
#######################################################################

# All the blocks used in the BO3 are listed here. Possible blocks:
# Block(x,y,z,id[.data][,nbtfile.nbt)
# RandomBlock(x,y,z,id[:data][,nbtfile.nbt],chance[,id[:data][,nbtfile.nbt],chance[,...]])
# So RandomBlock(0,0,0,CHEST,chest.nbt,50,CHEST,anotherchest.nbt,100) will spawn a chest at
# the BO3 origin, and give it a 50% chance to have the contents of chest.nbt, or, if that
# fails, a 100% percent chance to have the contents of anotherchest.nbt.
Block(-7,6,-1,STONE)
Block(-7,7,-1,GRASS)
Block(-7,7,0,STONE)
Block(-7,8,0,GRASS)
Block(-6,4,-1,STONE)
Block(-6,5,-1,STONE)
Block(-6,5,0,STONE)
Block(-6,6,-2,STONE)
Block(-6,6,-1,STONE)
Block(-6,6,0,STONE)
Block(-6,7,-2,GRASS)
Block(-6,7,-1,STONE)
Block(-6,7,0,STONE)
Block(-6,7,1,STONE)
Block(-6,8,-1,GRASS)
Block(-6,8,0,GRASS)
Block(-6,8,1,DIRT)
Block(-6,9,1,GRASS)
Block(-5,5,-1,STONE)
Block(-5,6,-1,DIRT)
Block(-5,6,0,STONE)
Block(-5,7,-1,GRASS)
Block(-5,7,0,DIRT)
Block(-5,8,0,GRASS)
Block(-2,9,-8,STONE)
Block(-2,9,-7,STONE)
Block(-2,9,-6,STONE)
Block(-2,10,-8,GRASS)
Block(-2,10,-7,DIRT)
Block(-2,10,-6,DIRT)
Block(-2,11,-7,GRASS)
Block(-2,11,-6,GRASS)
Block(-1,6,-11,STONE)
Block(-1,6,-10,STONE)
Block(-1,7,-11,STONE)
Block(-1,7,-10,STONE)
Block(-1,7,-9,STONE)
Block(-1,8,-11,DIRT)
Block(-1,8,-10,DIRT)
Block(-1,8,-9,STONE)
Block(-1,8,-8,STONE)
Block(-1,8,-7,STONE)
Block(-1,8,-6,STONE)
Block(-1,9,-11,GRASS)
Block(-1,9,-10,DIRT)
Block(-1,9,-9,STONE)
Block(-1,9,-8,STONE)
Block(-1,9,-7,STONE)
Block(-1,9,-6,STONE)
Block(-1,9,-5,STONE)
Block(-1,10,-10,GRASS)
Block(-1,10,-9,DIRT)
Block(-1,10,-8,DIRT)
Block(-1,10,-7,DIRT)
Block(-1,10,-6,DIRT)
Block(-1,10,-5,DIRT)
Block(-1,10,-4,STONE)
Block(-1,11,-9,GRASS)
Block(-1,11,-8,GRASS)
Block(-1,11,-7,GRASS)
Block(-1,11,-6,GRASS)
Block(-1,11,-5,GRASS)
Block(-1,11,-4,DIRT)
Block(-1,11,-3,STONE)
Block(-1,11,-2,STONE)
Block(-1,11,-1,STONE)
Block(-1,12,-4,GRASS)
Block(-1,12,-3,GRASS)
Block(-1,12,-2,DIRT)
Block(-1,12,-1,DIRT)
Block(-1,13,-2,GRASS)
Block(-1,13,-1,GRASS)
Block(0,5,-12,STONE)
Block(0,5,-11,STONE)
Block(0,6,-14,DIRT)
Block(0,6,-13,STONE)
Block(0,6,-12,STONE)
Block(0,6,-11,STONE)
Block(0,6,-10,STONE)
Block(0,7,-14,GRASS)
Block(0,7,-13,DIRT)
Block(0,7,-12,STONE)
Block(0,7,-11,STONE)
Block(0,7,-10,STONE)
Block(0,7,-9,STONE)
Block(0,7,-8,STONE)
Block(0,8,-13,GRASS)
Block(0,8,-12,DIRT)
Block(0,8,-11,DIRT)
Block(0,8,-10,DIRT)
Block(0,8,-9,STONE)
Block(0,8,-8,STONE)
Block(0,8,-7,STONE)
Block(0,8,-6,STONE)
Block(0,9,-12,GRASS)
Block(0,9,-11,GRASS)
Block(0,9,-10,DIRT)
Block(0,9,-9,STONE)
Block(0,9,-8,STONE)
Block(0,9,-7,STONE)
Block(0,9,-6,STONE)
Block(0,9,-5,STONE)
Block(0,10,-10,GRASS)
Block(0,10,-9,DIRT)
Block(0,10,-8,DIRT)
Block(0,10,-7,DIRT)
Block(0,10,-6,STONE)
Block(0,10,-5,STONE)
Block(0,10,-4,STONE)
Block(0,10,-3,STONE)
Block(0,10,-2,STONE)
Block(0,11,-9,GRASS)
Block(0,11,-8,GRASS)
Block(0,11,-7,GRASS)
Block(0,11,-6,DIRT)
Block(0,11,-5,DIRT)
Block(0,11,-4,STONE)
Block(0,11,-3,STONE)
Block(0,11,-2,STONE)
Block(0,11,-1,STONE)
Block(0,11,0,STONE)
Block(0,12,-6,GRASS)
Block(0,12,-5,GRASS)
Block(0,12,-4,DIRT)
Block(0,12,-3,DIRT)
Block(0,12,-2,DIRT)
Block(0,12,-1,DIRT)
Block(0,12,0,DIRT)
Block(0,13,-4,GRASS)
Block(0,13,-3,GRASS)
Block(0,13,-2,GRASS)
Block(0,13,-1,GRASS)
Block(0,13,0,GRASS)
Block(1,3,-12,STONE)
Block(1,4,-13,STONE)
Block(1,4,-12,STONE)
Block(1,4,-11,STONE)
Block(1,5,-12,STONE)
Block(1,5,-11,STONE)
Block(1,5,-10,STONE)
Block(1,5,-9,STONE)
Block(1,5,14,STONE)
Block(1,6,-14,STONE)
Block(1,6,-13,STONE)
Block(1,6,-12,STONE)
Block(1,6,-11,STONE)
Block(1,6,-10,STONE)
Block(1,6,-9,STONE)
Block(1,6,-8,STONE)
Block(1,6,-7,STONE)
Block(1,6,13,STONE)
Block(1,6,14,STONE)
Block(1,7,-14,DIRT)
Block(1,7,-13,DIRT)
Block(1,7,-12,STONE)
Block(1,7,-11,STONE)
Block(1,7,-10,STONE)
Block(1,7,-9,STONE)
Block(1,7,-8,STONE)
Block(1,7,-7,STONE)
Block(1,7,-6,STONE)
Block(1,7,12,STONE)
Block(1,7,13,STONE)
Block(1,7,14,DIRT)
Block(1,8,-14,GRASS)
Block(1,8,-13,GRASS)
Block(1,8,-12,DIRT)
Block(1,8,-11,DIRT)
Block(1,8,-10,DIRT)
Block(1,8,-9,STONE)
Block(1,8,-8,STONE)
Block(1,8,-7,STONE)
Block(1,8,-6,STONE)
Block(1,8,-5,STONE)
Block(1,8,11,STONE)
Block(1,8,12,STONE)
Block(1,8,13,DIRT)
Block(1,8,14,GRASS)
Block(1,9,-12,GRASS)
Block(1,9,-11,GRASS)
Block(1,9,-10,DIRT)
Block(1,9,-9,STONE)
Block(1,9,-8,STONE)
Block(1,9,-7,STONE)
Block(1,9,-6,STONE)
Block(1,9,-5,STONE)
Block(1,9,-4,STONE)
Block(1,9,-3,STONE)
Block(1,9,10,STONE)
Block(1,9,11,STONE)
Block(1,9,12,DIRT)
Block(1,9,13,GRASS)
Block(1,10,-10,GRASS)
Block(1,10,-9,GRASS)
Block(1,10,-8,DIRT)
Block(1,10,-7,DIRT)
Block(1,10,-6,STONE)
Block(1,10,-5,STONE)
Block(1,10,-4,STONE)
Block(1,10,-3,STONE)
Block(1,10,-2,STONE)
Block(1,10,-1,STONE)
Block(1,10,8,STONE)
Block(1,10,9,STONE)
Block(1,10,10,STONE)
Block(1,10,11,DIRT)
Block(1,10,12,GRASS)
Block(1,11,-8,GRASS)
Block(1,11,-7,GRASS)
Block(1,11,-6,DIRT)
Block(1,11,-5,DIRT)
Block(1,11,-4,DIRT)
Block(1,11,-3,STONE)
Block(1,11,-2,STONE)
Block(1,11,-1,STONE)
Block(1,11,0,STONE)
Block(1,11,1,STONE)
Block(1,11,8,DIRT)
Block(1,11,9,GRASS)
Block(1,11,10,GRASS)
Block(1,11,11,GRASS)
Block(1,12,-6,GRASS)
Block(1,12,-5,GRASS)
Block(1,12,-4,GRASS)
Block(1,12,-3,DIRT)
Block(1,12,-2,DIRT)
Block(1,12,-1,DIRT)
Block(1,12,0,DIRT)
Block(1,12,1,GRASS)
Block(1,12,8,GRASS)
Block(1,13,-3,GRASS)
Block(1,13,-2,DIRT)
Block(1,13,-1,DIRT)
Block(1,13,0,GRASS)
Block(1,14,-2,GRASS)
Block(1,14,-1,GRASS)
Block(2,0,-12,STONE)
Block(2,1,-13,STONE)
Block(2,1,-12,STONE)
Block(2,2,-14,STONE)
Block(2,2,-13,STONE)
Block(2,2,-12,STONE)
Block(2,3,-14,STONE)
Block(2,3,-13,STONE)
Block(2,3,-12,STONE)
Block(2,3,-11,STONE)
Block(2,3,14,STONE)
Block(2,4,-14,STONE)
Block(2,4,-13,STONE)
Block(2,4,-12,STONE)
Block(2,4,-11,STONE)
Block(2,4,-10,STONE)
Block(2,4,14,STONE)
Block(2,4,15,STONE)
Block(2,5,-15,STONE)
Block(2,5,-14,STONE)
Block(2,5,-13,STONE)
Block(2,5,-12,STONE)
Block(2,5,-11,STONE)
Block(2,5,-10,STONE)
Block(2,5,-9,STONE)
Block(2,5,-8,STONE)
Block(2,5,-7,STONE)
Block(2,5,13,STONE)
Block(2,5,14,STONE)
Block(2,5,15,STONE)
Block(2,6,-15,DIRT)
Block(2,6,-14,STONE)
Block(2,6,-13,STONE)
Block(2,6,-12,STONE)
Block(2,6,-11,STONE)
Block(2,6,-10,STONE)
Block(2,6,-9,STONE)
Block(2,6,-8,STONE)
Block(2,6,-7,STONE)
Block(2,6,-6,STONE)
Block(2,6,-5,STONE)
Block(2,6,13,STONE)
Block(2,6,14,STONE)
Block(2,6,15,STONE)
Block(2,7,-15,GRASS)
Block(2,7,-14,DIRT)
Block(2,7,-13,DIRT)
Block(2,7,-12,STONE)
Block(2,7,-11,STONE)
Block(2,7,-10,STONE)
Block(2,7,-9,STONE)
Block(2,7,-8,STONE)
Block(2,7,-7,STONE)
Block(2,7,-6,STONE)
Block(2,7,-5,STONE)
Block(2,7,12,STONE)
Block(2,7,13,STONE)
Block(2,7,14,STONE)
Block(2,7,15,STONE)
Block(2,8,-14,GRASS)
Block(2,8,-13,GRASS)
Block(2,8,-12,DIRT)
Block(2,8,-11,DIRT)
Block(2,8,-10,DIRT)
Block(2,8,-9,STONE)
Block(2,8,-8,STONE)
Block(2,8,-7,STONE)
Block(2,8,-6,STONE)
Block(2,8,-5,STONE)
Block(2,8,-4,STONE)
Block(2,8,-3,STONE)
Block(2,8,10,STONE)
Block(2,8,11,STONE)
Block(2,8,12,STONE)
Block(2,8,13,STONE)
Block(2,8,14,STONE)
Block(2,8,15,GRASS)
Block(2,9,-12,GRASS)
Block(2,9,-11,GRASS)
Block(2,9,-10,GRASS)
Block(2,9,-9,DIRT)
Block(2,9,-8,STONE)
Block(2,9,-7,STONE)
Block(2,9,-6,STONE)
Block(2,9,-5,STONE)
Block(2,9,-4,STONE)
Block(2,9,-3,STONE)
Block(2,9,-2,STONE)
Block(2,9,-1,STONE)
Block(2,9,8,STONE)
Block(2,9,9,STONE)
Block(2,9,10,STONE)
Block(2,9,11,STONE)
Block(2,9,12,STONE)
Block(2,9,13,STONE)
Block(2,9,14,GRASS)
Block(2,10,-9,GRASS)
Block(2,10,-8,DIRT)
Block(2,10,-7,DIRT)
Block(2,10,-6,STONE)
Block(2,10,-5,STONE)
Block(2,10,-4,STONE)
Block(2,10,-3,STONE)
Block(2,10,-2,STONE)
Block(2,10,-1,STONE)
Block(2,10,0,STONE)
Block(2,10,1,STONE)
Block(2,10,7,STONE)
Block(2,10,8,STONE)
Block(2,10,9,STONE)
Block(2,10,10,STONE)
Block(2,10,11,STONE)
Block(2,10,12,STONE)
Block(2,10,13,GRASS)
Block(2,11,-8,GRASS)
Block(2,11,-7,GRASS)
Block(2,11,-6,DIRT)
Block(2,11,-5,DIRT)
Block(2,11,-4,DIRT)
Block(2,11,-3,STONE)
Block(2,11,-2,STONE)
Block(2,11,-1,STONE)
Block(2,11,0,STONE)
Block(2,11,1,STONE)
Block(2,11,2,STONE)
Block(2,11,7,GRASS)
Block(2,11,8,DIRT)
Block(2,11,9,DIRT)
Block(2,11,10,GRASS)
Block(2,11,11,GRASS)
Block(2,11,12,GRASS)
Block(2,12,-6,GRASS)
Block(2,12,-5,GRASS)
Block(2,12,-4,GRASS)
Block(2,12,-3,DIRT)
Block(2,12,-2,DIRT)
Block(2,12,-1,DIRT)
Block(2,12,0,DIRT)
Block(2,12,1,DIRT)
Block(2,12,2,GRASS)
Block(2,12,8,DIRT)
Block(2,12,9,GRASS)
Block(2,13,-3,GRASS)
Block(2,13,-2,DIRT)
Block(2,13,-1,DIRT)
Block(2,13,0,DIRT)
Block(2,13,1,DIRT)
Block(2,13,8,GRASS)
Block(2,14,-2,GRASS)
Block(2,14,-1,DIRT)
Block(2,14,0,DIRT)
Block(2,14,1,GRASS)
Block(2,15,-1,GRASS)
Block(2,15,0,DIRT)
Block(2,16,0,GRASS)
Block(3,2,-12,STONE)
Block(3,3,-13,STONE)
Block(3,3,-12,STONE)
Block(3,3,-11,STONE)
Block(3,3,8,STONE)
Block(3,3,9,STONE)
Block(3,4,-14,STONE)
Block(3,4,-13,STONE)
Block(3,4,-12,STONE)
Block(3,4,-11,STONE)
Block(3,4,-10,STONE)
Block(3,4,7,STONE)
Block(3,4,8,DIRT)
Block(3,4,9,GRASS)
Block(3,5,-14,STONE)
Block(3,5,-13,STONE)
Block(3,5,-12,STONE)
Block(3,5,-11,STONE)
Block(3,5,-10,STONE)
Block(3,5,-9,STONE)
Block(3,5,7,GRASS)
Block(3,5,8,GRASS)
Block(3,6,-15,STONE)
Block(3,6,-14,STONE)
Block(3,6,-13,STONE)
Block(3,6,-12,STONE)
Block(3,6,-11,STONE)
Block(3,6,-10,STONE)
Block(3,6,-9,STONE)
Block(3,6,-8,STONE)
Block(3,6,14,STONE)
Block(3,7,-15,GRASS)
Block(3,7,-14,DIRT)
Block(3,7,-13,DIRT)
Block(3,7,-12,STONE)
Block(3,7,-11,STONE)
Block(3,7,-10,STONE)
Block(3,7,-9,STONE)
Block(3,7,-8,STONE)
Block(3,7,-7,STONE)
Block(3,7,-6,STONE)
Block(3,7,-5,STONE)
Block(3,7,13,STONE)
Block(3,7,14,STONE)
Block(3,8,-14,GRASS)
Block(3,8,-13,GRASS)
Block(3,8,-12,DIRT)
Block(3,8,-11,DIRT)
Block(3,8,-10,DIRT)
Block(3,8,-9,STONE)
Block(3,8,-8,STONE)
Block(3,8,-7,STONE)
Block(3,8,-6,STONE)
Block(3,8,-5,STONE)
Block(3,8,-4,STONE)
Block(3,8,12,STONE)
Block(3,8,13,DIRT)
Block(3,8,14,GRASS)
Block(3,9,-12,GRASS)
Block(3,9,-11,GRASS)
Block(3,9,-10,GRASS)
Block(3,9,-9,DIRT)
Block(3,9,-8,STONE)
Block(3,9,-7,STONE)
Block(3,9,-6,STONE)
Block(3,9,-5,STONE)
Block(3,9,-4,STONE)
Block(3,9,-3,STONE)
Block(3,9,10,STONE)
Block(3,9,11,STONE)
Block(3,9,12,DIRT)
Block(3,9,13,GRASS)
Block(3,10,-9,GRASS)
Block(3,10,-8,DIRT)
Block(3,10,-7,STONE)
Block(3,10,-6,STONE)
Block(3,10,-5,STONE)
Block(3,10,-4,STONE)
Block(3,10,-3,STONE)
Block(3,10,-2,STONE)
Block(3,10,-1,STONE)
Block(3,10,0,STONE)
Block(3,10,9,STONE)
Block(3,10,10,STONE)
Block(3,10,11,GRASS)
Block(3,10,12,GRASS)
Block(3,11,-8,GRASS)
Block(3,11,-7,DIRT)
Block(3,11,-6,DIRT)
Block(3,11,-5,DIRT)
Block(3,11,-4,DIRT)
Block(3,11,-3,STONE)
Block(3,11,-2,STONE)
Block(3,11,-1,STONE)
Block(3,11,0,STONE)
Block(3,11,1,STONE)
Block(3,11,9,DIRT)
Block(3,11,10,GRASS)
Block(3,12,-7,GRASS)
Block(3,12,-6,GRASS)
Block(3,12,-5,GRASS)
Block(3,12,-4,GRASS)
Block(3,12,-3,DIRT)
Block(3,12,-2,DIRT)
Block(3,12,-1,DIRT)
Block(3,12,0,DIRT)
Block(3,12,1,DIRT)
Block(3,12,9,GRASS)
Block(3,13,-3,GRASS)
Block(3,13,-2,DIRT)
Block(3,13,-1,DIRT)
Block(3,13,0,DIRT)
Block(3,13,1,GRASS)
Block(3,14,-2,GRASS)
Block(3,14,-1,GRASS)
Block(3,14,0,DIRT)
Block(3,15,0,GRASS)
Block(4,1,8,STONE)
Block(4,2,8,STONE)
Block(4,2,9,STONE)
Block(4,3,-12,STONE)
Block(4,3,7,STONE)
Block(4,3,8,STONE)
Block(4,3,9,DIRT)
Block(4,4,-12,STONE)
Block(4,4,7,STONE)
Block(4,4,8,STONE)
Block(4,4,9,DIRT)
Block(4,5,-13,STONE)
Block(4,5,-12,STONE)
Block(4,5,-11,STONE)
Block(4,5,6,STONE)
Block(4,5,7,STONE)
Block(4,5,8,DIRT)
Block(4,5,9,GRASS)
Block(4,6,-14,STONE)
Block(4,6,-13,STONE)
Block(4,6,-12,STONE)
Block(4,6,-11,STONE)
Block(4,6,-10,STONE)
Block(4,6,-9,STONE)
Block(4,6,6,DIRT)
Block(4,6,7,GRASS)
Block(4,6,8,GRASS)
Block(4,7,-14,DIRT)
Block(4,7,-13,DIRT)
Block(4,7,-12,STONE)
Block(4,7,-11,STONE)
Block(4,7,-10,STONE)
Block(4,7,-9,STONE)
Block(4,7,-8,STONE)
Block(4,7,-7,STONE)
Block(4,7,6,GRASS)
Block(4,8,-14,GRASS)
Block(4,8,-13,GRASS)
Block(4,8,-12,DIRT)
Block(4,8,-11,DIRT)
Block(4,8,-10,DIRT)
Block(4,8,-9,STONE)
Block(4,8,-8,STONE)
Block(4,8,-7,STONE)
Block(4,8,-6,STONE)
Block(4,8,-5,STONE)
Block(4,9,-12,GRASS)
Block(4,9,-11,GRASS)
Block(4,9,-10,DIRT)
Block(4,9,-9,DIRT)
Block(4,9,-8,STONE)
Block(4,9,-7,STONE)
Block(4,9,-6,STONE)
Block(4,9,-5,STONE)
Block(4,9,-4,STONE)
Block(4,10,-10,GRASS)
Block(4,10,-9,GRASS)
Block(4,10,-8,DIRT)
Block(4,10,-7,STONE)
Block(4,10,-6,STONE)
Block(4,10,-5,STONE)
Block(4,10,-4,STONE)
Block(4,10,-3,STONE)
Block(4,10,-2,STONE)
Block(4,11,-8,GRASS)
Block(4,11,-7,DIRT)
Block(4,11,-6,DIRT)
Block(4,11,-5,DIRT)
Block(4,11,-4,DIRT)
Block(4,11,-3,STONE)
Block(4,11,-2,STONE)
Block(4,11,-1,STONE)
Block(4,11,0,STONE)
Block(4,12,-7,GRASS)
Block(4,12,-6,GRASS)
Block(4,12,-5,GRASS)
Block(4,12,-4,GRASS)
Block(4,12,-3,DIRT)
Block(4,12,-2,DIRT)
Block(4,12,-1,DIRT)
Block(4,12,0,DIRT)
Block(4,13,-3,GRASS)
Block(4,13,-2,GRASS)
Block(4,13,-1,DIRT)
Block(4,13,0,GRASS)
Block(4,14,-1,GRASS)
Block(5,3,8,STONE)
Block(5,4,7,STONE)
Block(5,4,8,GRASS)
Block(5,5,-12,STONE)
Block(5,5,7,DIRT)
Block(5,6,-14,DIRT)
Block(5,6,-13,STONE)
Block(5,6,-12,STONE)
Block(5,6,-11,STONE)
Block(5,6,-10,STONE)
Block(5,6,7,GRASS)
Block(5,7,-14,GRASS)
Block(5,7,-13,DIRT)
Block(5,7,-12,STONE)
Block(5,7,-11,STONE)
Block(5,7,-10,STONE)
Block(5,7,-9,STONE)
Block(5,7,-8,STONE)
Block(5,7,-7,STONE)
Block(5,8,-13,GRASS)
Block(5,8,-12,GRASS)
Block(5,8,-11,DIRT)
Block(5,8,-10,DIRT)
Block(5,8,-9,STONE)
Block(5,8,-8,STONE)
Block(5,8,-7,STONE)
Block(5,9,-11,GRASS)
Block(5,9,-10,DIRT)
Block(5,9,-9,DIRT)
Block(5,9,-8,STONE)
Block(5,9,-7,STONE)
Block(5,9,-6,STONE)
Block(5,9,-5,STONE)
Block(5,9,-4,STONE)
Block(5,10,-10,GRASS)
Block(5,10,-9,GRASS)
Block(5,10,-8,GRASS)
Block(5,10,-7,DIRT)
Block(5,10,-6,STONE)
Block(5,10,-5,STONE)
Block(5,10,-4,STONE)
Block(5,10,-3,STONE)
Block(5,11,-7,GRASS)
Block(5,11,-6,DIRT)
Block(5,11,-5,DIRT)
Block(5,11,-4,DIRT)
Block(5,11,-3,STONE)
Block(5,11,-2,STONE)
Block(5,11,-1,STONE)
Block(5,11,0,STONE)
Block(5,12,-6,GRASS)
Block(5,12,-5,GRASS)
Block(5,12,-4,GRASS)
Block(5,12,-3,DIRT)
Block(5,12,-2,DIRT)
Block(5,12,-1,DIRT)
Block(5,12,0,DIRT)
Block(5,13,-3,GRASS)
Block(5,13,-2,GRASS)
Block(5,13,-1,GRASS)
Block(5,13,0,GRASS)
Block(6,6,-11,STONE)
Block(6,7,-11,GRASS)
Block(6,7,-10,STONE)
Block(6,8,-10,GRASS)
Block(6,8,-9,STONE)
Block(6,8,-8,STONE)
Block(6,8,-7,STONE)
Block(6,9,-9,GRASS)
Block(6,9,-8,GRASS)
Block(6,9,-7,STONE)
Block(6,9,-6,STONE)
Block(6,9,-5,STONE)
Block(6,10,-7,GRASS)
Block(6,10,-6,DIRT)
Block(6,10,-5,STONE)
Block(6,10,-4,STONE)
Block(6,11,-6,GRASS)
Block(6,11,-5,DIRT)
Block(6,11,-4,DIRT)
Block(6,11,-3,STONE)
Block(6,11,-2,STONE)
Block(6,12,-5,GRASS)
Block(6,12,-4,GRASS)
Block(6,12,-3,DIRT)
Block(6,12,-2,DIRT)
Block(6,13,-3,GRASS)
Block(6,13,-2,GRASS)

#######################################################################
# +-----------------------------------------------------------------+ #
# |                            BO3 checks                           | #
# +-----------------------------------------------------------------+ #
#######################################################################

# Require a condition at a certain location in order for the BO3 to be spawned.
# BlockCheck(x,y,z,BlockName[,BlockName[,...]]) - one of the blocks must be at the location
# BlockCheckNot(x,y,z,BlockName[,BlockName[,...]]) - all the blocks must not be at the location
# LightCheck(x,y,z,minLightLevel,maxLightLevel) - light must be between min and max (inclusive)

# You can use "Solid" as a BlockName for matching all solid blocks or "All" to match all blocks that aren't air.

# Examples:
#   BlockCheck(0,-1,0,GRASS,DIRT)  Require grass or dirt just below the object
#   BlockCheck(0,-1,0,Solid)       Require any solid block just below the object
#   BlockCheck(0,-1,0,WOOL)        Require any type of wool just below the object
#   BlockCheck(0,-1,0,WOOL:0)      Require white wool just below the object
#   BlockCheckNot(0,-1,0,WOOL:0)   Require that there is no white wool below the object
#   LightCheck(0,0,0,0,1)          Require almost complete darkness just below the object

#######################################################################
# +-----------------------------------------------------------------+ #
# |                             Branches                            | #
# +-----------------------------------------------------------------+ #
#######################################################################

# Branches are objects that will spawn when this object spawns when it is used in
# the CustomStructure resource. Branches can also have branches, making complex
# structures possible. See the wiki for more details.

# Regular Branches spawn each branch with an independent chance of spawning.
# Branch(x,y,z,branchName,rotation,chance[,anotherBranchName,rotation,chance[,...]][IndividualChance])
# branchName - name of the object to spawn.
# rotation - NORTH, SOUTH, EAST or WEST.
# IndividualChance - The chance each branch has to spawn, assumed to be 100 when left blank

# Weighted Branches spawn branches with a dependent chance of spawning.
# WeightedBranch(x,y,z,branchName,rotation,chance[,anotherBranchName,rotation,chance[,...]][MaxChanceOutOf])
# MaxChanceOutOf - The chance all branches have to spawn out of, assumed to be 100 when left blank
