
#######################################################################
# +-----------------------------------------------------------------+ #
# |                            BO3 object                           | #
# +-----------------------------------------------------------------+ #
#######################################################################

# This is the config file of a custom object.
# If you add this object correctly to your BiomeConfigs, it will spawn in the world.

# This is the creator of this BO3 object
Author: EmptyStar

# A short description of this BO3 object
Description: No description given

# The BO3 version, don't change this! It can be used by external applications to do a version check.
Version: 3

# The settings mode, WriteAll, WriteWithoutComments or WriteDisable. See WorldConfig.
SettingsMode: WriteDisable


#######################################################################
# +-----------------------------------------------------------------+ #
# |                          Main settings                          | #
# +-----------------------------------------------------------------+ #
#######################################################################

# This needs to be set to true to spawn the object in the Tree and Sapling resources.
Tree: false

# The frequency of the BO3 from 1 to 200. Tries this many times to spawn this BO3 when using the CustomObject(...) resource.
# Ignored by Tree(..), Sapling(..) and CustomStructure(..)
Frequency: 1

# The rarity of the BO3 from 0 to 100. Each spawn attempt has rarity% chance to succeed when using the CustomObject(...) resource.
# Ignored by Tree(..), Sapling(..) and CustomStructure(..)
Rarity: 0.125

# If you set this to true, the BO3 will be placed with a random rotation.
RotateRandomly: true

# The spawn height of the BO3 - randomY, highestBlock or highestSolidBlock.
SpawnHeight: randomY

# The offset from the spawn height to spawn this BO3
# Ex. SpawnHeight = highestSolidBlock, SpawnHeightOffset = 3; This object will spawn 3 blocks above the highest solid block
SpawnHeightOffset: 0

# A random amount to offset the spawn location from the spawn offset height
# Ex. SpawnHeightOffset = 3, SpawnHeightVariance = 3; This object will spawn 3 to 6 blocks above the original spot it would have spawned
SpawnHeightVariance: 0

######################
# Extrusion settings #
######################

# The style of extrusion you wish to use - BottomDown, TopUp, None (Default)
ExtrudeMode: None

# The blocks to extrude your BO3 through
ExtrudeThroughBlocks: AIR

# The height limits for the BO3.
MinHeight: 0

MaxHeight: 255

# Objects can have other objects attacthed to it: branches. Branches can also
# have branches attached to it, which can also have branches, etc. This is the
# maximum branch depth for this objects.
MaxBranchDepth: 1024

# When spawned with the UseWorld keyword, this BO3 should NOT spawn in the following biomes.
# If you writer.write the BO3 name directly in the BiomeConfigs, this will be ignored.
ExcludedBiomes: All


#######################################################################
# +-----------------------------------------------------------------+ #
# |                      Source block settings                      | #
# +-----------------------------------------------------------------+ #
#######################################################################

# The block(s) the BO3 should spawn in.
SourceBlocks: AIR

# The maximum percentage of the BO3 that can be outside the SourceBlock.
# The BO3 won't be placed on a location with more blocks outside the SourceBlock than this percentage.
MaxPercentageOutsideSourceBlock: 20

# What to do when a block is about to be placed outside the SourceBlock? (dontPlace, placeAnyway)
OutsideSourceBlock: placeAnyway


#######################################################################
# +-----------------------------------------------------------------+ #
# |                              Blocks                             | #
# +-----------------------------------------------------------------+ #
#######################################################################

# All the blocks used in the BO3 are listed here. Possible blocks:
# Block(x,y,z,id[.data][,nbtfile.nbt)
# RandomBlock(x,y,z,id[:data][,nbtfile.nbt],chance[,id[:data][,nbtfile.nbt],chance[,...]])
# So RandomBlock(0,0,0,CHEST,chest.nbt,50,CHEST,anotherchest.nbt,100) will spawn a chest at
# the BO3 origin, and give it a 50% chance to have the contents of chest.nbt, or, if that
# fails, a 100% percent chance to have the contents of anotherchest.nbt.
Block(-11,23,-5,STONE)
Block(-11,24,-5,STONE)
Block(-11,25,-5,STONE)
Block(-11,25,-4,STONE)
Block(-11,26,-5,GRASS)
Block(-11,26,-4,STONE)
Block(-11,26,-3,STONE)
Block(-11,27,-4,GRASS)
Block(-11,27,-3,GRASS)
Block(-9,6,-6,STONE)
Block(-9,7,-7,STONE)
Block(-9,7,-6,STONE)
Block(-9,8,-7,STONE)
Block(-9,8,-6,GRASS)
Block(-9,9,-7,GRASS)
Block(-9,24,7,STONE)
Block(-9,25,7,GRASS)
Block(-8,22,9,STONE)
Block(-8,23,8,STONE)
Block(-8,23,9,GRASS)
Block(-8,24,7,STONE)
Block(-8,24,8,DIRT)
Block(-8,25,5,STONE)
Block(-8,25,6,STONE)
Block(-8,25,7,DIRT)
Block(-8,25,8,GRASS)
Block(-8,26,5,GRASS)
Block(-8,26,6,DIRT)
Block(-8,26,7,GRASS)
Block(-8,27,6,GRASS)
Block(-7,20,9,STONE)
Block(-7,21,9,STONE)
Block(-7,21,10,STONE)
Block(-7,22,8,STONE)
Block(-7,22,9,STONE)
Block(-7,22,10,STONE)
Block(-7,23,4,STONE)
Block(-7,23,7,STONE)
Block(-7,23,8,STONE)
Block(-7,23,9,STONE)
Block(-7,23,10,GRASS)
Block(-7,24,4,STONE)
Block(-7,24,5,STONE)
Block(-7,24,6,STONE)
Block(-7,24,7,STONE)
Block(-7,24,8,GRASS)
Block(-7,24,9,GRASS)
Block(-7,25,4,STONE)
Block(-7,25,5,STONE)
Block(-7,25,6,STONE)
Block(-7,25,7,DIRT)
Block(-7,26,4,DIRT)
Block(-7,26,5,DIRT)
Block(-7,26,6,GRASS)
Block(-7,26,7,GRASS)
Block(-7,27,4,GRASS)
Block(-7,27,5,DIRT)
Block(-7,28,5,GRASS)
Block(-6,21,9,STONE)
Block(-6,22,8,STONE)
Block(-6,22,9,DIRT)
Block(-6,23,7,STONE)
Block(-6,23,8,GRASS)
Block(-6,23,9,GRASS)
Block(-6,24,4,STONE)
Block(-6,24,6,STONE)
Block(-6,24,7,DIRT)
Block(-6,25,4,GRASS)
Block(-6,25,5,STONE)
Block(-6,25,6,STONE)
Block(-6,25,7,GRASS)
Block(-6,26,5,GRASS)
Block(-6,26,6,GRASS)
Block(-4,6,-11,STONE)
Block(-4,7,-12,STONE)
Block(-4,7,-11,GRASS)
Block(-4,8,-13,STONE)
Block(-4,8,-12,GRASS)
Block(-4,9,-14,STONE)
Block(-4,9,-13,DIRT)
Block(-4,9,1,STONE)
Block(-4,10,-14,GRASS)
Block(-4,10,-13,DIRT)
Block(-4,10,0,STONE)
Block(-4,10,1,STONE)
Block(-4,10,2,STONE)
Block(-4,11,-13,GRASS)
Block(-4,11,0,STONE)
Block(-4,11,1,GRASS)
Block(-4,11,2,GRASS)
Block(-4,12,0,GRASS)
Block(-3,4,-10,STONE)
Block(-3,5,-11,STONE)
Block(-3,5,-10,STONE)
Block(-3,5,-9,STONE)
Block(-3,6,-12,STONE)
Block(-3,6,-11,STONE)
Block(-3,6,-10,DIRT)
Block(-3,6,-9,GRASS)
Block(-3,7,-13,STONE)
Block(-3,7,-12,STONE)
Block(-3,7,-11,DIRT)
Block(-3,7,-10,GRASS)
Block(-3,8,-14,STONE)
Block(-3,8,-13,STONE)
Block(-3,8,-12,DIRT)
Block(-3,8,-11,GRASS)
Block(-3,8,0,STONE)
Block(-3,8,1,STONE)
Block(-3,8,2,STONE)
Block(-3,9,-14,STONE)
Block(-3,9,-13,DIRT)
Block(-3,9,-12,GRASS)
Block(-3,9,-1,STONE)
Block(-3,9,0,STONE)
Block(-3,9,1,STONE)
Block(-3,9,2,STONE)
Block(-3,9,3,STONE)
Block(-3,10,-14,DIRT)
Block(-3,10,-13,GRASS)
Block(-3,10,-1,STONE)
Block(-3,10,0,STONE)
Block(-3,10,1,STONE)
Block(-3,10,2,STONE)
Block(-3,10,3,STONE)
Block(-3,11,-14,DIRT)
Block(-3,11,-1,DIRT)
Block(-3,11,0,DIRT)
Block(-3,11,1,DIRT)
Block(-3,11,2,DIRT)
Block(-3,11,3,DIRT)
Block(-3,12,-14,GRASS)
Block(-3,12,-1,DIRT)
Block(-3,12,0,DIRT)
Block(-3,12,1,DIRT)
Block(-3,12,2,DIRT)
Block(-3,12,3,DIRT)
Block(-3,13,-1,GRASS)
Block(-3,13,0,GRASS)
Block(-3,13,1,GRASS)
Block(-3,13,2,GRASS)
Block(-3,13,3,GRASS)
Block(-2,2,12,STONE)
Block(-2,2,13,STONE)
Block(-2,3,12,GRASS)
Block(-2,3,13,DIRT)
Block(-2,3,14,STONE)
Block(-2,4,13,GRASS)
Block(-2,4,14,DIRT)
Block(-2,5,14,GRASS)
Block(-2,6,-11,STONE)
Block(-2,7,-12,STONE)
Block(-2,7,-11,DIRT)
Block(-2,7,1,STONE)
Block(-2,7,2,STONE)
Block(-2,8,-13,STONE)
Block(-2,8,-12,DIRT)
Block(-2,8,-11,DIRT)
Block(-2,8,-3,STONE)
Block(-2,8,-2,STONE)
Block(-2,8,-1,STONE)
Block(-2,8,0,STONE)
Block(-2,8,1,STONE)
Block(-2,8,2,STONE)
Block(-2,8,3,STONE)
Block(-2,9,-13,DIRT)
Block(-2,9,-12,GRASS)
Block(-2,9,-11,GRASS)
Block(-2,9,-4,STONE)
Block(-2,9,-3,STONE)
Block(-2,9,-2,STONE)
Block(-2,9,-1,STONE)
Block(-2,9,0,STONE)
Block(-2,9,1,STONE)
Block(-2,9,2,STONE)
Block(-2,9,3,STONE)
Block(-2,9,4,STONE)
Block(-2,10,-13,GRASS)
Block(-2,10,-4,STONE)
Block(-2,10,-3,STONE)
Block(-2,10,-2,STONE)
Block(-2,10,-1,STONE)
Block(-2,10,0,STONE)
Block(-2,10,1,STONE)
Block(-2,10,2,STONE)
Block(-2,10,3,STONE)
Block(-2,10,4,STONE)
Block(-2,11,-4,DIRT)
Block(-2,11,-3,DIRT)
Block(-2,11,-2,DIRT)
Block(-2,11,-1,DIRT)
Block(-2,11,0,DIRT)
Block(-2,11,1,DIRT)
Block(-2,11,2,DIRT)
Block(-2,11,3,DIRT)
Block(-2,11,4,DIRT)
Block(-2,12,-4,DIRT)
Block(-2,12,-3,DIRT)
Block(-2,12,-2,DIRT)
Block(-2,12,-1,DIRT)
Block(-2,12,0,DIRT)
Block(-2,12,1,DIRT)
Block(-2,12,2,DIRT)
Block(-2,12,3,DIRT)
Block(-2,12,4,DIRT)
Block(-2,13,-4,GRASS)
Block(-2,13,-3,GRASS)
Block(-2,13,-2,DIRT)
Block(-2,13,-1,DIRT)
Block(-2,13,0,DIRT)
Block(-2,13,1,DIRT)
Block(-2,13,2,DIRT)
Block(-2,13,3,GRASS)
Block(-2,13,4,GRASS)
Block(-2,14,-2,GRASS)
Block(-2,14,-1,GRASS)
Block(-2,14,0,GRASS)
Block(-2,14,1,GRASS)
Block(-2,14,2,GRASS)
Block(-1,0,11,STONE)
Block(-1,1,11,STONE)
Block(-1,1,12,STONE)
Block(-1,1,13,STONE)
Block(-1,2,9,STONE)
Block(-1,2,10,STONE)
Block(-1,2,11,STONE)
Block(-1,2,12,STONE)
Block(-1,2,13,STONE)
Block(-1,3,9,GRASS)
Block(-1,3,10,STONE)
Block(-1,3,11,STONE)
Block(-1,3,12,STONE)
Block(-1,3,13,STONE)
Block(-1,3,14,STONE)
Block(-1,4,10,GRASS)
Block(-1,4,11,DIRT)
Block(-1,4,12,STONE)
Block(-1,4,13,STONE)
Block(-1,4,14,STONE)
Block(-1,5,11,GRASS)
Block(-1,5,12,DIRT)
Block(-1,5,13,STONE)
Block(-1,5,14,STONE)
Block(-1,6,-1,STONE)
Block(-1,6,0,STONE)
Block(-1,6,1,STONE)
Block(-1,6,12,GRASS)
Block(-1,6,13,DIRT)
Block(-1,6,14,STONE)
Block(-1,7,-3,STONE)
Block(-1,7,-2,STONE)
Block(-1,7,-1,STONE)
Block(-1,7,0,STONE)
Block(-1,7,1,STONE)
Block(-1,7,2,STONE)
Block(-1,7,3,STONE)
Block(-1,7,13,GRASS)
Block(-1,7,14,DIRT)
Block(-1,8,-4,STONE)
Block(-1,8,-3,STONE)
Block(-1,8,-2,STONE)
Block(-1,8,-1,STONE)
Block(-1,8,0,STONE)
Block(-1,8,1,STONE)
Block(-1,8,2,STONE)
Block(-1,8,3,STONE)
Block(-1,8,4,STONE)
Block(-1,8,14,DIRT)
Block(-1,9,-5,STONE)
Block(-1,9,-4,STONE)
Block(-1,9,-3,STONE)
Block(-1,9,-2,STONE)
Block(-1,9,-1,STONE)
Block(-1,9,0,STONE)
Block(-1,9,1,STONE)
Block(-1,9,2,STONE)
Block(-1,9,3,STONE)
Block(-1,9,4,STONE)
Block(-1,9,5,STONE)
Block(-1,9,14,GRASS)
Block(-1,10,-6,STONE)
Block(-1,10,-5,STONE)
Block(-1,10,-4,STONE)
Block(-1,10,-3,STONE)
Block(-1,10,-2,STONE)
Block(-1,10,-1,STONE)
Block(-1,10,0,STONE)
Block(-1,10,1,STONE)
Block(-1,10,2,STONE)
Block(-1,10,3,STONE)
Block(-1,10,4,STONE)
Block(-1,10,5,STONE)
Block(-1,10,6,STONE)
Block(-1,11,-6,DIRT)
Block(-1,11,-5,DIRT)
Block(-1,11,-4,DIRT)
Block(-1,11,-3,DIRT)
Block(-1,11,-2,DIRT)
Block(-1,11,-1,DIRT)
Block(-1,11,0,DIRT)
Block(-1,11,1,DIRT)
Block(-1,11,2,DIRT)
Block(-1,11,3,DIRT)
Block(-1,11,4,DIRT)
Block(-1,11,5,DIRT)
Block(-1,11,6,GRASS)
Block(-1,12,-6,GRASS)
Block(-1,12,-5,DIRT)
Block(-1,12,-4,DIRT)
Block(-1,12,-3,DIRT)
Block(-1,12,-2,DIRT)
Block(-1,12,-1,DIRT)
Block(-1,12,0,DIRT)
Block(-1,12,1,DIRT)
Block(-1,12,2,DIRT)
Block(-1,12,3,DIRT)
Block(-1,12,4,DIRT)
Block(-1,12,5,DIRT)
Block(-1,13,-5,GRASS)
Block(-1,13,-4,DIRT)
Block(-1,13,-3,DIRT)
Block(-1,13,-2,DIRT)
Block(-1,13,-1,DIRT)
Block(-1,13,0,DIRT)
Block(-1,13,1,DIRT)
Block(-1,13,2,DIRT)
Block(-1,13,3,DIRT)
Block(-1,13,4,DIRT)
Block(-1,13,5,GRASS)
Block(-1,14,-4,GRASS)
Block(-1,14,-3,GRASS)
Block(-1,14,-2,DIRT)
Block(-1,14,-1,DIRT)
Block(-1,14,0,DIRT)
Block(-1,14,1,DIRT)
Block(-1,14,2,GRASS)
Block(-1,14,3,GRASS)
Block(-1,14,4,GRASS)
Block(-1,15,-2,GRASS)
Block(-1,15,-1,GRASS)
Block(-1,15,0,GRASS)
Block(-1,15,1,GRASS)
Block(0,1,11,STONE)
Block(0,2,11,STONE)
Block(0,2,12,STONE)
Block(0,2,13,STONE)
Block(0,3,11,GRASS)
Block(0,3,12,STONE)
Block(0,3,13,DIRT)
Block(0,4,12,GRASS)
Block(0,4,13,DIRT)
Block(0,5,13,GRASS)
Block(0,7,-1,STONE)
Block(0,7,0,STONE)
Block(0,8,-3,STONE)
Block(0,8,-2,STONE)
Block(0,8,-1,STONE)
Block(0,8,0,STONE)
Block(0,8,1,STONE)
Block(0,8,2,STONE)
Block(0,9,-5,STONE)
Block(0,9,-4,STONE)
Block(0,9,-3,STONE)
Block(0,9,-2,STONE)
Block(0,9,-1,STONE)
Block(0,9,0,STONE)
Block(0,9,1,STONE)
Block(0,9,2,STONE)
Block(0,9,3,STONE)
Block(0,9,4,STONE)
Block(0,9,5,STONE)
Block(0,10,-6,STONE)
Block(0,10,-5,STONE)
Block(0,10,-4,STONE)
Block(0,10,-3,STONE)
Block(0,10,-2,STONE)
Block(0,10,-1,STONE)
Block(0,10,0,STONE)
Block(0,10,1,STONE)
Block(0,10,2,STONE)
Block(0,10,3,STONE)
Block(0,10,4,STONE)
Block(0,10,5,STONE)
Block(0,10,6,STONE)
Block(0,11,-6,GRASS)
Block(0,11,-5,DIRT)
Block(0,11,-4,DIRT)
Block(0,11,-3,DIRT)
Block(0,11,-2,DIRT)
Block(0,11,-1,DIRT)
Block(0,11,0,DIRT)
Block(0,11,1,DIRT)
Block(0,11,2,DIRT)
Block(0,11,3,DIRT)
Block(0,11,4,DIRT)
Block(0,11,5,DIRT)
Block(0,11,6,DIRT)
Block(0,12,-5,DIRT)
Block(0,12,-4,DIRT)
Block(0,12,-3,DIRT)
Block(0,12,-2,DIRT)
Block(0,12,-1,DIRT)
Block(0,12,0,DIRT)
Block(0,12,1,DIRT)
Block(0,12,2,DIRT)
Block(0,12,3,DIRT)
Block(0,12,4,DIRT)
Block(0,12,5,DIRT)
Block(0,12,6,GRASS)
Block(0,13,-5,GRASS)
Block(0,13,-4,GRASS)
Block(0,13,-3,DIRT)
Block(0,13,-2,DIRT)
Block(0,13,-1,DIRT)
Block(0,13,0,DIRT)
Block(0,13,1,DIRT)
Block(0,13,2,DIRT)
Block(0,13,3,DIRT)
Block(0,13,4,GRASS)
Block(0,13,5,GRASS)
Block(0,14,-3,GRASS)
Block(0,14,-2,GRASS)
Block(0,14,-1,DIRT)
Block(0,14,0,DIRT)
Block(0,14,1,DIRT)
Block(0,14,2,DIRT)
Block(0,14,3,GRASS)
Block(0,15,-1,GRASS)
Block(0,15,0,GRASS)
Block(0,15,1,GRASS)
Block(0,15,2,GRASS)
Block(1,8,-1,STONE)
Block(1,8,0,STONE)
Block(1,9,-3,STONE)
Block(1,9,-2,STONE)
Block(1,9,-1,STONE)
Block(1,9,0,STONE)
Block(1,9,1,STONE)
Block(1,9,2,STONE)
Block(1,10,-3,STONE)
Block(1,10,-2,STONE)
Block(1,10,-1,STONE)
Block(1,10,0,STONE)
Block(1,10,1,STONE)
Block(1,10,2,STONE)
Block(1,10,3,STONE)
Block(1,11,-3,DIRT)
Block(1,11,-2,DIRT)
Block(1,11,-1,DIRT)
Block(1,11,0,DIRT)
Block(1,11,1,DIRT)
Block(1,11,2,DIRT)
Block(1,11,3,DIRT)
Block(1,12,-3,GRASS)
Block(1,12,-2,DIRT)
Block(1,12,-1,DIRT)
Block(1,12,0,DIRT)
Block(1,12,1,DIRT)
Block(1,12,2,DIRT)
Block(1,12,3,GRASS)
Block(1,13,-2,GRASS)
Block(1,13,-1,GRASS)
Block(1,13,0,GRASS)
Block(1,13,1,GRASS)
Block(1,13,2,GRASS)
Block(2,9,-1,STONE)
Block(2,9,0,STONE)
Block(2,10,-1,STONE)
Block(2,10,0,STONE)
Block(2,10,1,STONE)
Block(2,11,-1,GRASS)
Block(2,11,0,GRASS)
Block(2,11,1,GRASS)
Block(2,12,0,GRASS)
Block(7,5,5,STONE)
Block(7,6,5,STONE)
Block(7,6,6,STONE)
Block(7,7,5,GRASS)
Block(7,7,6,STONE)
Block(7,7,7,STONE)
Block(7,8,6,GRASS)
Block(7,8,7,DIRT)
Block(7,9,7,GRASS)
Block(8,22,-5,STONE)
Block(8,23,-5,STONE)
Block(8,24,-5,GRASS)
Block(9,21,-7,STONE)
Block(9,21,-5,STONE)
Block(9,22,-7,GRASS)
Block(9,22,-6,STONE)
Block(9,22,-5,STONE)
Block(9,22,-4,STONE)
Block(9,23,-6,GRASS)
Block(9,23,-5,STONE)
Block(9,23,-4,GRASS)
Block(9,24,-5,DIRT)
Block(9,25,-5,GRASS)
Block(10,19,-7,STONE)
Block(10,20,-8,STONE)
Block(10,20,-7,STONE)
Block(10,20,-6,STONE)
Block(10,21,-8,STONE)
Block(10,21,-7,STONE)
Block(10,21,-6,STONE)
Block(10,21,-5,STONE)
Block(10,21,-4,STONE)
Block(10,22,-8,GRASS)
Block(10,22,-7,STONE)
Block(10,22,-6,STONE)
Block(10,22,-5,STONE)
Block(10,22,-4,STONE)
Block(10,22,-3,STONE)
Block(10,23,-7,GRASS)
Block(10,23,-6,STONE)
Block(10,23,-5,STONE)
Block(10,23,-4,STONE)
Block(10,23,-3,STONE)
Block(10,23,-2,STONE)
Block(10,23,-1,STONE)
Block(10,24,-6,GRASS)
Block(10,24,-5,STONE)
Block(10,24,-4,STONE)
Block(10,24,-3,DIRT)
Block(10,24,-2,GRASS)
Block(10,24,-1,GRASS)
Block(10,25,-5,DIRT)
Block(10,25,-4,DIRT)
Block(10,25,-3,GRASS)
Block(10,26,-5,DIRT)
Block(10,26,-4,GRASS)
Block(10,27,-5,GRASS)
Block(11,21,-7,STONE)
Block(11,22,-7,GRASS)
Block(11,22,-6,STONE)
Block(11,23,-6,DIRT)
Block(11,23,-5,STONE)
Block(11,23,-4,STONE)
Block(11,24,-6,GRASS)
Block(11,24,-5,DIRT)
Block(11,24,-4,GRASS)
Block(11,25,-5,GRASS)

#######################################################################
# +-----------------------------------------------------------------+ #
# |                            BO3 checks                           | #
# +-----------------------------------------------------------------+ #
#######################################################################

# Require a condition at a certain location in order for the BO3 to be spawned.
# BlockCheck(x,y,z,BlockName[,BlockName[,...]]) - one of the blocks must be at the location
# BlockCheckNot(x,y,z,BlockName[,BlockName[,...]]) - all the blocks must not be at the location
# LightCheck(x,y,z,minLightLevel,maxLightLevel) - light must be between min and max (inclusive)

# You can use "Solid" as a BlockName for matching all solid blocks or "All" to match all blocks that aren't air.

# Examples:
#   BlockCheck(0,-1,0,GRASS,DIRT)  Require grass or dirt just below the object
#   BlockCheck(0,-1,0,Solid)       Require any solid block just below the object
#   BlockCheck(0,-1,0,WOOL)        Require any type of wool just below the object
#   BlockCheck(0,-1,0,WOOL:0)      Require white wool just below the object
#   BlockCheckNot(0,-1,0,WOOL:0)   Require that there is no white wool below the object
#   LightCheck(0,0,0,0,1)          Require almost complete darkness just below the object

#######################################################################
# +-----------------------------------------------------------------+ #
# |                             Branches                            | #
# +-----------------------------------------------------------------+ #
#######################################################################

# Branches are objects that will spawn when this object spawns when it is used in
# the CustomStructure resource. Branches can also have branches, making complex
# structures possible. See the wiki for more details.

# Regular Branches spawn each branch with an independent chance of spawning.
# Branch(x,y,z,branchName,rotation,chance[,anotherBranchName,rotation,chance[,...]][IndividualChance])
# branchName - name of the object to spawn.
# rotation - NORTH, SOUTH, EAST or WEST.
# IndividualChance - The chance each branch has to spawn, assumed to be 100 when left blank

# Weighted Branches spawn branches with a dependent chance of spawning.
# WeightedBranch(x,y,z,branchName,rotation,chance[,anotherBranchName,rotation,chance[,...]][MaxChanceOutOf])
# MaxChanceOutOf - The chance all branches have to spawn out of, assumed to be 100 when left blank
