
#######################################################################
# +-----------------------------------------------------------------+ #
# |                            BO3 object                           | #
# +-----------------------------------------------------------------+ #
#######################################################################

# This is the config file of a custom object.
# If you add this object correctly to your BiomeConfigs, it will spawn in the world.

# This is the creator of this BO3 object
Author: EmptyStar

# A short description of this BO3 object
Description: No description given

# The BO3 version, don't change this! It can be used by external applications to do a version check.
Version: 3

# The settings mode, WriteAll, WriteWithoutComments or WriteDisable. See WorldConfig.
SettingsMode: WriteDisable


#######################################################################
# +-----------------------------------------------------------------+ #
# |                          Main settings                          | #
# +-----------------------------------------------------------------+ #
#######################################################################

# This needs to be set to true to spawn the object in the Tree and Sapling resources.
Tree: false

# The frequency of the BO3 from 1 to 200. Tries this many times to spawn this BO3 when using the CustomObject(...) resource.
# Ignored by Tree(..), Sapling(..) and CustomStructure(..)
Frequency: 1

# The rarity of the BO3 from 0 to 100. Each spawn attempt has rarity% chance to succeed when using the CustomObject(...) resource.
# Ignored by Tree(..), Sapling(..) and CustomStructure(..)
Rarity: 100.0

# If you set this to true, the BO3 will be placed with a random rotation.
RotateRandomly: false

# The spawn height of the BO3 - randomY, highestBlock or highestSolidBlock.
SpawnHeight: highestBlock

# The offset from the spawn height to spawn this BO3
# Ex. SpawnHeight = highestSolidBlock, SpawnHeightOffset = 3; This object will spawn 3 blocks above the highest solid block
SpawnHeightOffset: 0

# A random amount to offset the spawn location from the spawn offset height
# Ex. SpawnHeightOffset = 3, SpawnHeightVariance = 3; This object will spawn 3 to 6 blocks above the original spot it would have spawned
SpawnHeightVariance: 0

######################
# Extrusion settings #
######################

# The style of extrusion you wish to use - BottomDown, TopUp, None (Default)
ExtrudeMode: None

# The blocks to extrude your BO3 through
ExtrudeThroughBlocks: AIR

# The height limits for the BO3.
MinHeight: 0

MaxHeight: 256

# Objects can have other objects attacthed to it: branches. Branches can also
# have branches attached to it, which can also have branches, etc. This is the
# maximum branch depth for this objects.
MaxBranchDepth: 10

# When spawned with the UseWorld keyword, this BO3 should NOT spawn in the following biomes.
# If you writer.write the BO3 name directly in the BiomeConfigs, this will be ignored.
ExcludedBiomes: All


#######################################################################
# +-----------------------------------------------------------------+ #
# |                      Source block settings                      | #
# +-----------------------------------------------------------------+ #
#######################################################################

# The block(s) the BO3 should spawn in.
SourceBlocks: AIR

# The maximum percentage of the BO3 that can be outside the SourceBlock.
# The BO3 won't be placed on a location with more blocks outside the SourceBlock than this percentage.
MaxPercentageOutsideSourceBlock: 100

# What to do when a block is about to be placed outside the SourceBlock? (dontPlace, placeAnyway)
OutsideSourceBlock: placeAnyway


#######################################################################
# +-----------------------------------------------------------------+ #
# |                              Blocks                             | #
# +-----------------------------------------------------------------+ #
#######################################################################

# All the blocks used in the BO3 are listed here. Possible blocks:
# Block(x,y,z,id[.data][,nbtfile.nbt)
# RandomBlock(x,y,z,id[:data][,nbtfile.nbt],chance[,id[:data][,nbtfile.nbt],chance[,...]])
# So RandomBlock(0,0,0,CHEST,chest.nbt,50,CHEST,anotherchest.nbt,100) will spawn a chest at
# the BO3 origin, and give it a 50% chance to have the contents of chest.nbt, or, if that
# fails, a 100% percent chance to have the contents of anotherchest.nbt.
Block(-8,0,6,STONE)
Block(-8,0,7,STONE)
Block(-8,1,1,STONE)
Block(-8,1,2,STONE)
Block(-8,1,3,STONE)
Block(-8,1,4,STONE)
Block(-8,1,5,STONE)
Block(-8,1,6,STONE)
Block(-8,1,7,STONE)
Block(-8,2,-5,STONE)
Block(-8,2,-4,STONE)
Block(-8,2,-3,STONE)
Block(-8,2,-2,STONE)
Block(-8,2,-1,STONE)
Block(-8,2,0,STONE)
Block(-8,2,1,STONE)
Block(-8,2,2,STONE)
Block(-8,2,3,STONE)
Block(-8,2,4,STONE)
Block(-8,2,5,STONE)
Block(-8,2,6,STONE)
Block(-8,2,7,STONE)
Block(-8,3,-6,STONE)
Block(-8,3,-5,STONE)
Block(-8,3,-4,STONE)
Block(-8,3,-3,STONE)
Block(-8,3,-2,STONE)
Block(-8,3,-1,STONE)
Block(-8,3,0,DIRT)
Block(-8,3,1,DIRT)
Block(-8,3,2,DIRT)
Block(-8,3,3,DIRT)
Block(-8,3,4,DIRT)
Block(-8,3,5,DIRT)
Block(-8,3,6,DIRT)
Block(-8,3,7,DIRT)
Block(-8,4,-8,STONE)
Block(-8,4,-7,STONE)
Block(-8,4,-6,STONE)
Block(-8,4,-5,DIRT)
Block(-8,4,-4,DIRT)
Block(-8,4,-3,DIRT)
Block(-8,4,-2,DIRT)
Block(-8,4,-1,DIRT)
Block(-8,4,0,DIRT)
Block(-8,4,1,DIRT)
Block(-8,4,2,DIRT)
Block(-8,4,3,GRASS)
Block(-8,4,4,GRASS)
Block(-8,4,5,GRASS)
Block(-8,4,6,GRASS)
Block(-8,4,7,GRASS)
Block(-8,5,-8,DIRT)
Block(-8,5,-7,DIRT)
Block(-8,5,-6,DIRT)
Block(-8,5,-5,DIRT)
Block(-8,5,-4,DIRT)
Block(-8,5,-3,DIRT)
Block(-8,5,-2,DIRT)
Block(-8,5,-1,DIRT)
Block(-8,5,0,GRASS)
Block(-8,5,1,GRASS)
Block(-8,5,2,GRASS)
Block(-8,5,3,SPONGE)
Block(-8,5,4,SPONGE)
Block(-8,5,5,SPONGE)
Block(-8,5,6,SPONGE)
Block(-8,5,7,SPONGE)
Block(-8,6,-8,DIRT)
Block(-8,6,-7,GRASS)
Block(-8,6,-6,GRASS)
Block(-8,6,-5,GRASS)
Block(-8,6,-4,GRASS)
Block(-8,6,-3,GRASS)
Block(-8,6,-2,GRASS)
Block(-8,6,-1,GRASS)
Block(-8,6,0,SPONGE)
Block(-8,6,1,SPONGE)
Block(-8,6,2,SPONGE)
Block(-8,6,3,SPONGE)
Block(-8,6,4,SPONGE)
Block(-8,6,5,SPONGE)
Block(-8,6,6,SPONGE)
Block(-8,6,7,SPONGE)
Block(-8,7,-8,GRASS)
Block(-8,7,-7,SPONGE)
Block(-8,7,-6,SPONGE)
Block(-8,7,-5,SPONGE)
Block(-8,7,-4,SPONGE)
Block(-8,7,-3,SPONGE)
Block(-8,7,-2,SPONGE)
Block(-8,7,-1,SPONGE)
Block(-8,7,0,SPONGE)
Block(-8,7,1,SPONGE)
Block(-8,7,2,SPONGE)
Block(-8,7,3,SPONGE)
Block(-8,7,4,SPONGE)
Block(-8,7,5,SPONGE)
Block(-8,7,6,SPONGE)
Block(-8,7,7,SPONGE)
Block(-7,0,7,STONE)
Block(-7,1,4,STONE)
Block(-7,1,5,STONE)
Block(-7,1,6,STONE)
Block(-7,1,7,STONE)
Block(-7,2,-2,STONE)
Block(-7,2,-1,STONE)
Block(-7,2,0,STONE)
Block(-7,2,1,STONE)
Block(-7,2,2,STONE)
Block(-7,2,3,STONE)
Block(-7,2,4,STONE)
Block(-7,2,5,STONE)
Block(-7,2,6,STONE)
Block(-7,2,7,STONE)
Block(-7,3,-4,STONE)
Block(-7,3,-3,STONE)
Block(-7,3,-2,STONE)
Block(-7,3,-1,STONE)
Block(-7,3,0,DIRT)
Block(-7,3,1,DIRT)
Block(-7,3,2,DIRT)
Block(-7,3,3,DIRT)
Block(-7,3,4,DIRT)
Block(-7,3,5,DIRT)
Block(-7,3,6,DIRT)
Block(-7,3,7,DIRT)
Block(-7,4,-6,STONE)
Block(-7,4,-5,STONE)
Block(-7,4,-4,STONE)
Block(-7,4,-3,STONE)
Block(-7,4,-2,STONE)
Block(-7,4,-1,DIRT)
Block(-7,4,0,DIRT)
Block(-7,4,1,DIRT)
Block(-7,4,2,DIRT)
Block(-7,4,3,DIRT)
Block(-7,4,4,DIRT)
Block(-7,4,5,DIRT)
Block(-7,4,6,GRASS)
Block(-7,4,7,GRASS)
Block(-7,5,-8,STONE)
Block(-7,5,-7,STONE)
Block(-7,5,-6,STONE)
Block(-7,5,-5,DIRT)
Block(-7,5,-4,DIRT)
Block(-7,5,-3,DIRT)
Block(-7,5,-2,DIRT)
Block(-7,5,-1,DIRT)
Block(-7,5,0,DIRT)
Block(-7,5,1,DIRT)
Block(-7,5,2,GRASS)
Block(-7,5,3,GRASS)
Block(-7,5,4,GRASS)
Block(-7,5,5,GRASS)
Block(-7,5,6,SPONGE)
Block(-7,5,7,SPONGE)
Block(-7,6,-8,GRASS)
Block(-7,6,-7,DIRT)
Block(-7,6,-6,DIRT)
Block(-7,6,-5,GRASS)
Block(-7,6,-4,GRASS)
Block(-7,6,-3,GRASS)
Block(-7,6,-2,GRASS)
Block(-7,6,-1,GRASS)
Block(-7,6,0,GRASS)
Block(-7,6,1,GRASS)
Block(-7,6,2,SPONGE)
Block(-7,6,3,SPONGE)
Block(-7,6,4,SPONGE)
Block(-7,6,5,SPONGE)
Block(-7,6,6,SPONGE)
Block(-7,6,7,SPONGE)
Block(-7,7,-7,GRASS)
Block(-7,7,-6,GRASS)
Block(-7,7,-5,SPONGE)
Block(-7,7,-4,SPONGE)
Block(-7,7,-3,SPONGE)
Block(-7,7,-2,SPONGE)
Block(-7,7,-1,SPONGE)
Block(-7,7,0,SPONGE)
Block(-7,7,1,SPONGE)
Block(-7,7,2,SPONGE)
Block(-7,7,3,SPONGE)
Block(-7,7,4,SPONGE)
Block(-7,7,5,SPONGE)
Block(-7,7,6,SPONGE)
Block(-7,7,7,SPONGE)
Block(-6,1,5,STONE)
Block(-6,1,6,STONE)
Block(-6,1,7,STONE)
Block(-6,2,2,STONE)
Block(-6,2,3,STONE)
Block(-6,2,4,STONE)
Block(-6,2,5,STONE)
Block(-6,2,6,STONE)
Block(-6,2,7,STONE)
Block(-6,3,0,STONE)
Block(-6,3,1,STONE)
Block(-6,3,2,STONE)
Block(-6,3,3,DIRT)
Block(-6,3,4,DIRT)
Block(-6,3,5,DIRT)
Block(-6,3,6,DIRT)
Block(-6,3,7,DIRT)
Block(-6,4,-3,STONE)
Block(-6,4,-2,STONE)
Block(-6,4,-1,STONE)
Block(-6,4,0,STONE)
Block(-6,4,1,DIRT)
Block(-6,4,2,DIRT)
Block(-6,4,3,DIRT)
Block(-6,4,4,DIRT)
Block(-6,4,5,DIRT)
Block(-6,4,6,GRASS)
Block(-6,4,7,GRASS)
Block(-6,5,-7,STONE)
Block(-6,5,-6,STONE)
Block(-6,5,-5,STONE)
Block(-6,5,-4,STONE)
Block(-6,5,-3,DIRT)
Block(-6,5,-2,STONE)
Block(-6,5,-1,DIRT)
Block(-6,5,0,DIRT)
Block(-6,5,1,DIRT)
Block(-6,5,2,DIRT)
Block(-6,5,3,DIRT)
Block(-6,5,4,GRASS)
Block(-6,5,5,GRASS)
Block(-6,5,6,SPONGE)
Block(-6,5,7,SPONGE)
Block(-6,6,-7,GRASS)
Block(-6,6,-6,GRASS)
Block(-6,6,-5,DIRT)
Block(-6,6,-4,DIRT)
Block(-6,6,-3,DIRT)
Block(-6,6,-2,DIRT)
Block(-6,6,-1,GRASS)
Block(-6,6,0,GRASS)
Block(-6,6,1,GRASS)
Block(-6,6,2,GRASS)
Block(-6,6,3,GRASS)
Block(-6,6,4,SPONGE)
Block(-6,6,5,SPONGE)
Block(-6,6,6,SPONGE)
Block(-6,6,7,SPONGE)
Block(-6,7,-5,GRASS)
Block(-6,7,-4,GRASS)
Block(-6,7,-3,GRASS)
Block(-6,7,-2,GRASS)
Block(-6,7,-1,SPONGE)
Block(-6,7,0,SPONGE)
Block(-6,7,1,SPONGE)
Block(-6,7,2,SPONGE)
Block(-6,7,3,SPONGE)
Block(-6,7,4,SPONGE)
Block(-6,7,5,SPONGE)
Block(-6,7,6,SPONGE)
Block(-6,7,7,SPONGE)
Block(-5,1,7,STONE)
Block(-5,2,4,STONE)
Block(-5,2,5,STONE)
Block(-5,2,6,STONE)
Block(-5,2,7,STONE)
Block(-5,3,3,STONE)
Block(-5,3,4,DIRT)
Block(-5,3,5,DIRT)
Block(-5,3,6,DIRT)
Block(-5,3,7,DIRT)
Block(-5,4,-1,STONE)
Block(-5,4,0,STONE)
Block(-5,4,1,STONE)
Block(-5,4,2,STONE)
Block(-5,4,3,DIRT)
Block(-5,4,4,DIRT)
Block(-5,4,5,DIRT)
Block(-5,4,6,DIRT)
Block(-5,4,7,GRASS)
Block(-5,5,-5,STONE)
Block(-5,5,-4,STONE)
Block(-5,5,-3,STONE)
Block(-5,5,-2,STONE)
Block(-5,5,-1,STONE)
Block(-5,5,0,STONE)
Block(-5,5,1,DIRT)
Block(-5,5,2,DIRT)
Block(-5,5,3,DIRT)
Block(-5,5,4,DIRT)
Block(-5,5,5,GRASS)
Block(-5,5,6,GRASS)
Block(-5,5,7,SPONGE)
Block(-5,6,-5,GRASS)
Block(-5,6,-4,GRASS)
Block(-5,6,-3,GRASS)
Block(-5,6,-2,GRASS)
Block(-5,6,-1,DIRT)
Block(-5,6,0,DIRT)
Block(-5,6,1,GRASS)
Block(-5,6,2,GRASS)
Block(-5,6,3,GRASS)
Block(-5,6,4,GRASS)
Block(-5,6,5,SPONGE)
Block(-5,6,6,SPONGE)
Block(-5,6,7,SPONGE)
Block(-5,7,-1,GRASS)
Block(-5,7,0,GRASS)
Block(-5,7,1,SPONGE)
Block(-5,7,2,SPONGE)
Block(-5,7,3,SPONGE)
Block(-5,7,4,SPONGE)
Block(-5,7,5,SPONGE)
Block(-5,7,6,SPONGE)
Block(-5,7,7,SPONGE)
Block(-4,1,7,STONE)
Block(-4,2,5,STONE)
Block(-4,2,6,STONE)
Block(-4,2,7,STONE)
Block(-4,3,4,STONE)
Block(-4,3,5,DIRT)
Block(-4,3,6,DIRT)
Block(-4,3,7,DIRT)
Block(-4,4,2,STONE)
Block(-4,4,3,STONE)
Block(-4,4,4,DIRT)
Block(-4,4,5,DIRT)
Block(-4,4,6,DIRT)
Block(-4,4,7,DIRT)
Block(-4,5,-1,STONE)
Block(-4,5,0,STONE)
Block(-4,5,1,STONE)
Block(-4,5,2,STONE)
Block(-4,5,3,DIRT)
Block(-4,5,4,DIRT)
Block(-4,5,5,DIRT)
Block(-4,5,6,GRASS)
Block(-4,5,7,GRASS)
Block(-4,6,-1,GRASS)
Block(-4,6,0,GRASS)
Block(-4,6,1,DIRT)
Block(-4,6,2,DIRT)
Block(-4,6,3,GRASS)
Block(-4,6,4,GRASS)
Block(-4,6,5,GRASS)
Block(-4,6,6,SPONGE)
Block(-4,6,7,SPONGE)
Block(-4,7,1,GRASS)
Block(-4,7,2,GRASS)
Block(-4,7,3,SPONGE)
Block(-4,7,4,SPONGE)
Block(-4,7,5,SPONGE)
Block(-4,7,6,SPONGE)
Block(-4,7,7,SPONGE)
Block(-3,1,7,STONE)
Block(-3,2,5,STONE)
Block(-3,2,6,STONE)
Block(-3,2,7,STONE)
Block(-3,3,5,STONE)
Block(-3,3,6,DIRT)
Block(-3,3,7,DIRT)
Block(-3,4,3,STONE)
Block(-3,4,4,STONE)
Block(-3,4,5,DIRT)
Block(-3,4,6,DIRT)
Block(-3,4,7,DIRT)
Block(-3,5,1,STONE)
Block(-3,5,2,STONE)
Block(-3,5,3,STONE)
Block(-3,5,4,DIRT)
Block(-3,5,5,DIRT)
Block(-3,5,6,GRASS)
Block(-3,5,7,GRASS)
Block(-3,6,1,GRASS)
Block(-3,6,2,GRASS)
Block(-3,6,3,DIRT)
Block(-3,6,4,GRASS)
Block(-3,6,5,GRASS)
Block(-3,6,6,SPONGE)
Block(-3,6,7,SPONGE)
Block(-3,7,3,GRASS)
Block(-3,7,4,SPONGE)
Block(-3,7,5,SPONGE)
Block(-3,7,6,SPONGE)
Block(-3,7,7,SPONGE)
Block(-2,1,7,STONE)
Block(-2,2,5,STONE)
Block(-2,2,6,STONE)
Block(-2,2,7,STONE)
Block(-2,3,5,STONE)
Block(-2,3,6,DIRT)
Block(-2,3,7,DIRT)
Block(-2,4,4,STONE)
Block(-2,4,5,DIRT)
Block(-2,4,6,DIRT)
Block(-2,4,7,DIRT)
Block(-2,5,2,STONE)
Block(-2,5,3,STONE)
Block(-2,5,4,DIRT)
Block(-2,5,5,DIRT)
Block(-2,5,6,DIRT)
Block(-2,5,7,GRASS)
Block(-2,6,2,GRASS)
Block(-2,6,3,DIRT)
Block(-2,6,4,GRASS)
Block(-2,6,5,GRASS)
Block(-2,6,6,GRASS)
Block(-2,6,7,SPONGE)
Block(-2,7,3,GRASS)
Block(-2,7,4,SPONGE)
Block(-2,7,5,SPONGE)
Block(-2,7,6,SPONGE)
Block(-2,7,7,SPONGE)
Block(-1,2,6,STONE)
Block(-1,2,7,STONE)
Block(-1,3,5,STONE)
Block(-1,3,6,DIRT)
Block(-1,3,7,DIRT)
Block(-1,4,4,STONE)
Block(-1,4,5,STONE)
Block(-1,4,6,DIRT)
Block(-1,4,7,DIRT)
Block(-1,5,3,STONE)
Block(-1,5,4,DIRT)
Block(-1,5,5,DIRT)
Block(-1,5,6,DIRT)
Block(-1,5,7,GRASS)
Block(-1,6,3,GRASS)
Block(-1,6,4,DIRT)
Block(-1,6,5,GRASS)
Block(-1,6,6,GRASS)
Block(-1,6,7,SPONGE)
Block(-1,7,4,GRASS)
Block(-1,7,5,SPONGE)
Block(-1,7,6,SPONGE)
Block(-1,7,7,SPONGE)
Block(0,2,6,STONE)
Block(0,2,7,STONE)
Block(0,3,6,STONE)
Block(0,3,7,STONE)
Block(0,4,5,STONE)
Block(0,4,6,DIRT)
Block(0,4,7,DIRT)
Block(0,5,3,STONE)
Block(0,5,4,STONE)
Block(0,5,5,DIRT)
Block(0,5,6,DIRT)
Block(0,5,7,DIRT)
Block(0,6,3,GRASS)
Block(0,6,4,DIRT)
Block(0,6,5,GRASS)
Block(0,6,6,GRASS)
Block(0,6,7,GRASS)
Block(0,7,4,GRASS)
Block(0,7,5,SPONGE)
Block(0,7,6,SPONGE)
Block(0,7,7,SPONGE)
Block(1,2,7,STONE)
Block(1,3,6,STONE)
Block(1,3,7,STONE)
Block(1,4,5,STONE)
Block(1,4,6,STONE)
Block(1,4,7,DIRT)
Block(1,5,4,STONE)
Block(1,5,5,STONE)
Block(1,5,6,DIRT)
Block(1,5,7,DIRT)
Block(1,6,4,GRASS)
Block(1,6,5,DIRT)
Block(1,6,6,GRASS)
Block(1,6,7,GRASS)
Block(1,7,5,GRASS)
Block(1,7,6,SPONGE)
Block(1,7,7,SPONGE)
Block(2,2,7,STONE)
Block(2,3,6,STONE)
Block(2,3,7,STONE)
Block(2,4,5,STONE)
Block(2,4,6,STONE)
Block(2,4,7,DIRT)
Block(2,5,4,STONE)
Block(2,5,5,STONE)
Block(2,5,6,DIRT)
Block(2,5,7,DIRT)
Block(2,6,4,GRASS)
Block(2,6,5,DIRT)
Block(2,6,6,GRASS)
Block(2,6,7,GRASS)
Block(2,7,5,GRASS)
Block(2,7,6,SPONGE)
Block(2,7,7,SPONGE)
Block(3,2,7,STONE)
Block(3,3,6,STONE)
Block(3,3,7,STONE)
Block(3,4,5,STONE)
Block(3,4,6,STONE)
Block(3,4,7,DIRT)
Block(3,5,4,STONE)
Block(3,5,5,STONE)
Block(3,5,6,DIRT)
Block(3,5,7,DIRT)
Block(3,6,4,GRASS)
Block(3,6,5,DIRT)
Block(3,6,6,GRASS)
Block(3,6,7,GRASS)
Block(3,7,5,GRASS)
Block(3,7,6,SPONGE)
Block(3,7,7,SPONGE)
Block(4,2,7,STONE)
Block(4,3,7,STONE)
Block(4,4,5,STONE)
Block(4,4,6,STONE)
Block(4,4,7,DIRT)
Block(4,5,4,STONE)
Block(4,5,5,STONE)
Block(4,5,6,DIRT)
Block(4,5,7,DIRT)
Block(4,6,4,GRASS)
Block(4,6,5,DIRT)
Block(4,6,6,GRASS)
Block(4,6,7,GRASS)
Block(4,7,5,GRASS)
Block(4,7,6,SPONGE)
Block(4,7,7,SPONGE)
Block(5,4,5,STONE)
Block(5,4,6,STONE)
Block(5,4,7,STONE)
Block(5,5,5,STONE)
Block(5,5,6,STONE)
Block(5,5,7,DIRT)
Block(5,6,5,GRASS)
Block(5,6,6,DIRT)
Block(5,6,7,GRASS)
Block(5,7,6,GRASS)
Block(5,7,7,SPONGE)
Block(6,4,6,STONE)
Block(6,4,7,STONE)
Block(6,5,5,STONE)
Block(6,5,6,STONE)
Block(6,5,7,DIRT)
Block(6,6,5,GRASS)
Block(6,6,6,DIRT)
Block(6,6,7,GRASS)
Block(6,7,6,GRASS)
Block(6,7,7,SPONGE)
Block(7,4,7,STONE)
Block(7,5,6,STONE)
Block(7,5,7,DIRT)
Block(7,6,6,GRASS)
Block(7,6,7,DIRT)
Block(7,7,-8,WOOL:1)
Block(7,7,7,GRASS)

#######################################################################
# +-----------------------------------------------------------------+ #
# |                            BO3 checks                           | #
# +-----------------------------------------------------------------+ #
#######################################################################

# Require a condition at a certain location in order for the BO3 to be spawned.
# BlockCheck(x,y,z,BlockName[,BlockName[,...]]) - one of the blocks must be at the location
# BlockCheckNot(x,y,z,BlockName[,BlockName[,...]]) - all the blocks must not be at the location
# LightCheck(x,y,z,minLightLevel,maxLightLevel) - light must be between min and max (inclusive)

# You can use "Solid" as a BlockName for matching all solid blocks or "All" to match all blocks that aren't air.

# Examples:
#   BlockCheck(0,-1,0,GRASS,DIRT)  Require grass or dirt just below the object
#   BlockCheck(0,-1,0,Solid)       Require any solid block just below the object
#   BlockCheck(0,-1,0,WOOL)        Require any type of wool just below the object
#   BlockCheck(0,-1,0,WOOL:0)      Require white wool just below the object
#   BlockCheckNot(0,-1,0,WOOL:0)   Require that there is no white wool below the object
#   LightCheck(0,0,0,0,1)          Require almost complete darkness just below the object

#######################################################################
# +-----------------------------------------------------------------+ #
# |                             Branches                            | #
# +-----------------------------------------------------------------+ #
#######################################################################

# Branches are objects that will spawn when this object spawns when it is used in
# the CustomStructure resource. Branches can also have branches, making complex
# structures possible. See the wiki for more details.

# Regular Branches spawn each branch with an independent chance of spawning.
# Branch(x,y,z,branchName,rotation,chance[,anotherBranchName,rotation,chance[,...]][IndividualChance])
# branchName - name of the object to spawn.
# rotation - NORTH, SOUTH, EAST or WEST.
# IndividualChance - The chance each branch has to spawn, assumed to be 100 when left blank

# Weighted Branches spawn branches with a dependent chance of spawning.
# WeightedBranch(x,y,z,branchName,rotation,chance[,anotherBranchName,rotation,chance[,...]][MaxChanceOutOf])
# MaxChanceOutOf - The chance all branches have to spawn out of, assumed to be 100 when left blank
