
#######################################################################
# +-----------------------------------------------------------------+ #
# |                            BO3 object                           | #
# +-----------------------------------------------------------------+ #
#######################################################################

# This is the config file of a custom object.
# If you add this object correctly to your BiomeConfigs, it will spawn in the world.

# This is the creator of this BO3 object
Author: EmptyStar

# A short description of this BO3 object
Description: No description given

# The BO3 version, don't change this! It can be used by external applications to do a version check.
Version: 3

# The settings mode, WriteAll, WriteWithoutComments or WriteDisable. See WorldConfig.
SettingsMode: WriteDisable


#######################################################################
# +-----------------------------------------------------------------+ #
# |                          Main settings                          | #
# +-----------------------------------------------------------------+ #
#######################################################################

# This needs to be set to true to spawn the object in the Tree and Sapling resources.
Tree: false

# The frequency of the BO3 from 1 to 200. Tries this many times to spawn this BO3 when using the CustomObject(...) resource.
# Ignored by Tree(..), Sapling(..) and CustomStructure(..)
Frequency: 1

# The rarity of the BO3 from 0 to 100. Each spawn attempt has rarity% chance to succeed when using the CustomObject(...) resource.
# Ignored by Tree(..), Sapling(..) and CustomStructure(..)
Rarity: 100.0

# If you set this to true, the BO3 will be placed with a random rotation.
RotateRandomly: false

# The spawn height of the BO3 - randomY, highestBlock or highestSolidBlock.
SpawnHeight: highestBlock

# The offset from the spawn height to spawn this BO3
# Ex. SpawnHeight = highestSolidBlock, SpawnHeightOffset = 3; This object will spawn 3 blocks above the highest solid block
SpawnHeightOffset: 0

# A random amount to offset the spawn location from the spawn offset height
# Ex. SpawnHeightOffset = 3, SpawnHeightVariance = 3; This object will spawn 3 to 6 blocks above the original spot it would have spawned
SpawnHeightVariance: 0

######################
# Extrusion settings #
######################

# The style of extrusion you wish to use - BottomDown, TopUp, None (Default)
ExtrudeMode: None

# The blocks to extrude your BO3 through
ExtrudeThroughBlocks: AIR

# The height limits for the BO3.
MinHeight: 0

MaxHeight: 256

# Objects can have other objects attacthed to it: branches. Branches can also
# have branches attached to it, which can also have branches, etc. This is the
# maximum branch depth for this objects.
MaxBranchDepth: 10

# When spawned with the UseWorld keyword, this BO3 should NOT spawn in the following biomes.
# If you writer.write the BO3 name directly in the BiomeConfigs, this will be ignored.
ExcludedBiomes: All


#######################################################################
# +-----------------------------------------------------------------+ #
# |                      Source block settings                      | #
# +-----------------------------------------------------------------+ #
#######################################################################

# The block(s) the BO3 should spawn in.
SourceBlocks: AIR

# The maximum percentage of the BO3 that can be outside the SourceBlock.
# The BO3 won't be placed on a location with more blocks outside the SourceBlock than this percentage.
MaxPercentageOutsideSourceBlock: 100

# What to do when a block is about to be placed outside the SourceBlock? (dontPlace, placeAnyway)
OutsideSourceBlock: placeAnyway


#######################################################################
# +-----------------------------------------------------------------+ #
# |                              Blocks                             | #
# +-----------------------------------------------------------------+ #
#######################################################################

# All the blocks used in the BO3 are listed here. Possible blocks:
# Block(x,y,z,id[.data][,nbtfile.nbt)
# RandomBlock(x,y,z,id[:data][,nbtfile.nbt],chance[,id[:data][,nbtfile.nbt],chance[,...]])
# So RandomBlock(0,0,0,CHEST,chest.nbt,50,CHEST,anotherchest.nbt,100) will spawn a chest at
# the BO3 origin, and give it a 50% chance to have the contents of chest.nbt, or, if that
# fails, a 100% percent chance to have the contents of anotherchest.nbt.
Block(-8,0,15,WOOL:11)
Block(-8,4,-9,STONE)
Block(-8,4,-8,STONE)
Block(-8,4,-7,STONE)
Block(-8,4,-6,STONE)
Block(-8,4,-5,STONE)
Block(-8,4,-4,STONE)
Block(-8,4,-3,STONE)
Block(-8,5,-9,STONE)
Block(-8,5,-8,STONE)
Block(-8,5,-7,STONE)
Block(-8,5,-6,STONE)
Block(-8,5,-5,DIRT)
Block(-8,5,-4,GRASS)
Block(-8,5,-3,GRASS)
Block(-8,6,-9,GRASS)
Block(-8,6,-8,GRASS)
Block(-8,6,-7,GRASS)
Block(-8,6,-6,GRASS)
Block(-8,6,-5,GRASS)
Block(-7,3,-8,STONE)
Block(-7,3,-7,STONE)
Block(-7,3,-6,STONE)
Block(-7,3,-5,STONE)
Block(-7,3,-4,STONE)
Block(-7,4,-9,STONE)
Block(-7,4,-8,STONE)
Block(-7,4,-7,STONE)
Block(-7,4,-6,STONE)
Block(-7,4,-5,STONE)
Block(-7,4,-4,STONE)
Block(-7,4,-3,STONE)
Block(-7,4,-2,STONE)
Block(-7,4,-1,STONE)
Block(-7,4,0,STONE)
Block(-7,5,-9,STONE)
Block(-7,5,-8,STONE)
Block(-7,5,-7,STONE)
Block(-7,5,-6,STONE)
Block(-7,5,-5,STONE)
Block(-7,5,-4,STONE)
Block(-7,5,-3,GRASS)
Block(-7,5,-2,GRASS)
Block(-7,5,-1,GRASS)
Block(-7,5,0,GRASS)
Block(-7,6,-9,DIRT)
Block(-7,6,-8,GRASS)
Block(-7,6,-7,GRASS)
Block(-7,6,-6,GRASS)
Block(-7,6,-5,GRASS)
Block(-7,6,-4,GRASS)
Block(-7,7,-9,GRASS)
Block(-6,2,-7,STONE)
Block(-6,2,-6,STONE)
Block(-6,2,-5,STONE)
Block(-6,2,-4,STONE)
Block(-6,3,-8,STONE)
Block(-6,3,-7,STONE)
Block(-6,3,-6,STONE)
Block(-6,3,-5,STONE)
Block(-6,3,-4,STONE)
Block(-6,3,-3,STONE)
Block(-6,3,-2,STONE)
Block(-6,3,-1,STONE)
Block(-6,3,0,STONE)
Block(-6,3,1,STONE)
Block(-6,4,-11,STONE)
Block(-6,4,-10,STONE)
Block(-6,4,-9,STONE)
Block(-6,4,-8,STONE)
Block(-6,4,-7,STONE)
Block(-6,4,-6,STONE)
Block(-6,4,-5,STONE)
Block(-6,4,-4,STONE)
Block(-6,4,-3,STONE)
Block(-6,4,-2,STONE)
Block(-6,4,-1,STONE)
Block(-6,4,0,STONE)
Block(-6,4,1,STONE)
Block(-6,4,2,STONE)
Block(-6,5,-12,STONE)
Block(-6,5,-11,STONE)
Block(-6,5,-10,STONE)
Block(-6,5,-9,STONE)
Block(-6,5,-8,STONE)
Block(-6,5,-7,STONE)
Block(-6,5,-6,STONE)
Block(-6,5,-5,STONE)
Block(-6,5,-4,STONE)
Block(-6,5,-3,STONE)
Block(-6,5,-2,GRASS)
Block(-6,5,-1,GRASS)
Block(-6,5,0,GRASS)
Block(-6,5,1,GRASS)
Block(-6,5,2,GRASS)
Block(-6,6,-12,DIRT)
Block(-6,6,-11,STONE)
Block(-6,6,-10,STONE)
Block(-6,6,-9,DIRT)
Block(-6,6,-8,DIRT)
Block(-6,6,-7,GRASS)
Block(-6,6,-6,GRASS)
Block(-6,6,-5,GRASS)
Block(-6,6,-4,GRASS)
Block(-6,6,-3,GRASS)
Block(-6,7,-12,GRASS)
Block(-6,7,-11,DIRT)
Block(-6,7,-10,DIRT)
Block(-6,7,-9,GRASS)
Block(-6,7,-8,GRASS)
Block(-6,8,-11,DIRT)
Block(-6,8,-10,GRASS)
Block(-6,9,-11,GRASS)
Block(-5,1,-5,STONE)
Block(-5,2,-5,STONE)
Block(-5,2,-4,STONE)
Block(-5,2,-3,STONE)
Block(-5,2,-2,STONE)
Block(-5,3,-9,STONE)
Block(-5,3,-8,STONE)
Block(-5,3,-7,STONE)
Block(-5,3,-6,STONE)
Block(-5,3,-5,STONE)
Block(-5,3,-4,STONE)
Block(-5,3,-3,STONE)
Block(-5,3,-2,STONE)
Block(-5,3,-1,STONE)
Block(-5,3,0,STONE)
Block(-5,4,-11,STONE)
Block(-5,4,-10,STONE)
Block(-5,4,-9,STONE)
Block(-5,4,-8,STONE)
Block(-5,4,-7,STONE)
Block(-5,4,-6,STONE)
Block(-5,4,-5,STONE)
Block(-5,4,-4,STONE)
Block(-5,4,-3,STONE)
Block(-5,4,-2,STONE)
Block(-5,4,-1,STONE)
Block(-5,4,0,STONE)
Block(-5,4,1,STONE)
Block(-5,4,2,STONE)
Block(-5,5,-12,STONE)
Block(-5,5,-11,STONE)
Block(-5,5,-10,STONE)
Block(-5,5,-9,STONE)
Block(-5,5,-8,STONE)
Block(-5,5,-7,STONE)
Block(-5,5,-6,STONE)
Block(-5,5,-5,STONE)
Block(-5,5,-4,STONE)
Block(-5,5,-3,STONE)
Block(-5,5,-2,STONE)
Block(-5,5,-1,GRASS)
Block(-5,5,0,GRASS)
Block(-5,5,1,GRASS)
Block(-5,5,2,GRASS)
Block(-5,6,-12,GRASS)
Block(-5,6,-11,STONE)
Block(-5,6,-10,STONE)
Block(-5,6,-9,DIRT)
Block(-5,6,-8,DIRT)
Block(-5,6,-7,GRASS)
Block(-5,6,-6,GRASS)
Block(-5,6,-5,GRASS)
Block(-5,6,-4,GRASS)
Block(-5,6,-3,GRASS)
Block(-5,6,-2,GRASS)
Block(-5,7,-11,DIRT)
Block(-5,7,-10,DIRT)
Block(-5,7,-9,GRASS)
Block(-5,7,-8,GRASS)
Block(-5,8,-11,GRASS)
Block(-5,8,-10,GRASS)
Block(-4,2,-4,STONE)
Block(-4,3,-5,STONE)
Block(-4,3,-4,STONE)
Block(-4,3,-3,STONE)
Block(-4,3,-2,STONE)
Block(-4,3,-1,STONE)
Block(-4,4,-10,STONE)
Block(-4,4,-9,STONE)
Block(-4,4,-8,STONE)
Block(-4,4,-7,STONE)
Block(-4,4,-6,STONE)
Block(-4,4,-5,STONE)
Block(-4,4,-4,STONE)
Block(-4,4,-3,STONE)
Block(-4,4,-2,STONE)
Block(-4,4,-1,STONE)
Block(-4,4,0,STONE)
Block(-4,4,1,STONE)
Block(-4,5,-10,STONE)
Block(-4,5,-9,STONE)
Block(-4,5,-8,STONE)
Block(-4,5,-7,STONE)
Block(-4,5,-6,DIRT)
Block(-4,5,-5,GRASS)
Block(-4,5,-4,DIRT)
Block(-4,5,-3,STONE)
Block(-4,5,-2,GRASS)
Block(-4,5,-1,GRASS)
Block(-4,5,0,GRASS)
Block(-4,5,1,GRASS)
Block(-4,6,-10,DIRT)
Block(-4,6,-9,DIRT)
Block(-4,6,-8,GRASS)
Block(-4,6,-7,GRASS)
Block(-4,6,-6,GRASS)
Block(-4,6,-4,GRASS)
Block(-4,6,-3,GRASS)
Block(-4,7,-10,GRASS)
Block(-4,7,-9,GRASS)
Block(-3,2,10,STONE)
Block(-3,2,11,STONE)
Block(-3,3,8,STONE)
Block(-3,3,9,STONE)
Block(-3,3,10,STONE)
Block(-3,3,11,STONE)
Block(-3,3,12,STONE)
Block(-3,4,-5,STONE)
Block(-3,4,-4,STONE)
Block(-3,4,-3,STONE)
Block(-3,4,-2,STONE)
Block(-3,4,-1,STONE)
Block(-3,4,0,STONE)
Block(-3,4,8,GRASS)
Block(-3,4,9,GRASS)
Block(-3,4,10,GRASS)
Block(-3,4,11,GRASS)
Block(-3,4,12,GRASS)
Block(-3,5,-5,GRASS)
Block(-3,5,-4,GRASS)
Block(-3,5,-3,GRASS)
Block(-3,5,-2,GRASS)
Block(-3,5,-1,GRASS)
Block(-3,5,0,GRASS)
Block(-2,1,11,STONE)
Block(-2,2,8,STONE)
Block(-2,2,9,STONE)
Block(-2,2,10,STONE)
Block(-2,2,11,STONE)
Block(-2,2,12,STONE)
Block(-2,2,13,STONE)
Block(-2,2,14,STONE)
Block(-2,3,7,STONE)
Block(-2,3,8,STONE)
Block(-2,3,9,STONE)
Block(-2,3,10,STONE)
Block(-2,3,11,STONE)
Block(-2,3,12,STONE)
Block(-2,3,13,STONE)
Block(-2,3,14,STONE)
Block(-2,3,15,STONE)
Block(-2,4,-13,STONE)
Block(-2,4,-12,STONE)
Block(-2,4,7,GRASS)
Block(-2,4,8,GRASS)
Block(-2,4,9,STONE)
Block(-2,4,10,STONE)
Block(-2,4,11,STONE)
Block(-2,4,12,STONE)
Block(-2,4,13,GRASS)
Block(-2,4,14,GRASS)
Block(-2,4,15,GRASS)
Block(-2,5,-14,STONE)
Block(-2,5,-13,STONE)
Block(-2,5,-12,GRASS)
Block(-2,5,9,GRASS)
Block(-2,5,10,GRASS)
Block(-2,5,11,GRASS)
Block(-2,5,12,GRASS)
Block(-2,6,-14,GRASS)
Block(-2,6,-13,GRASS)
Block(-1,0,11,STONE)
Block(-1,1,10,STONE)
Block(-1,1,11,STONE)
Block(-1,1,12,STONE)
Block(-1,2,9,STONE)
Block(-1,2,10,STONE)
Block(-1,2,11,STONE)
Block(-1,2,12,STONE)
Block(-1,2,13,STONE)
Block(-1,3,-12,STONE)
Block(-1,3,7,STONE)
Block(-1,3,8,STONE)
Block(-1,3,9,STONE)
Block(-1,3,10,STONE)
Block(-1,3,11,STONE)
Block(-1,3,12,STONE)
Block(-1,3,13,STONE)
Block(-1,3,14,STONE)
Block(-1,3,15,STONE)
Block(-1,4,-13,STONE)
Block(-1,4,-12,STONE)
Block(-1,4,-11,STONE)
Block(-1,4,-10,STONE)
Block(-1,4,7,GRASS)
Block(-1,4,8,GRASS)
Block(-1,4,9,GRASS)
Block(-1,4,10,GRASS)
Block(-1,4,11,STONE)
Block(-1,4,12,STONE)
Block(-1,4,13,STONE)
Block(-1,4,14,GRASS)
Block(-1,4,15,GRASS)
Block(-1,5,-15,STONE)
Block(-1,5,-14,STONE)
Block(-1,5,-13,STONE)
Block(-1,5,-12,STONE)
Block(-1,5,-11,STONE)
Block(-1,5,-10,STONE)
Block(-1,5,-9,STONE)
Block(-1,5,11,GRASS)
Block(-1,5,12,GRASS)
Block(-1,5,13,GRASS)
Block(-1,6,-15,GRASS)
Block(-1,6,-14,STONE)
Block(-1,6,-13,STONE)
Block(-1,6,-12,GRASS)
Block(-1,6,-11,GRASS)
Block(-1,6,-10,GRASS)
Block(-1,6,-9,GRASS)
Block(-1,7,-14,GRASS)
Block(-1,7,-13,GRASS)
Block(0,1,11,STONE)
Block(0,2,10,STONE)
Block(0,2,11,STONE)
Block(0,2,12,STONE)
Block(0,3,9,STONE)
Block(0,3,10,STONE)
Block(0,3,11,STONE)
Block(0,3,12,STONE)
Block(0,3,13,STONE)
Block(0,3,14,STONE)
Block(0,4,-12,STONE)
Block(0,4,9,GRASS)
Block(0,4,10,GRASS)
Block(0,4,11,GRASS)
Block(0,4,12,GRASS)
Block(0,4,13,GRASS)
Block(0,4,14,GRASS)
Block(0,5,-14,STONE)
Block(0,5,-13,STONE)
Block(0,5,-12,STONE)
Block(0,5,-11,STONE)
Block(0,5,-10,STONE)
Block(0,6,-14,GRASS)
Block(0,6,-13,STONE)
Block(0,6,-12,STONE)
Block(0,6,-11,GRASS)
Block(0,6,-10,GRASS)
Block(0,7,-13,GRASS)
Block(0,7,-12,GRASS)
Block(1,5,-13,STONE)
Block(1,5,-12,STONE)
Block(1,6,-13,GRASS)
Block(1,6,-12,GRASS)
Block(2,4,-5,STONE)
Block(2,4,-4,STONE)
Block(2,4,-3,STONE)
Block(2,4,-2,STONE)
Block(2,4,-1,STONE)
Block(2,4,0,STONE)
Block(2,4,1,STONE)
Block(2,4,2,STONE)
Block(2,5,-5,GRASS)
Block(2,5,-4,GRASS)
Block(2,5,-3,GRASS)
Block(2,5,-2,GRASS)
Block(2,5,-1,GRASS)
Block(2,5,0,GRASS)
Block(2,5,1,GRASS)
Block(2,5,2,GRASS)
Block(3,3,-4,STONE)
Block(3,3,-3,STONE)
Block(3,3,-2,STONE)
Block(3,3,-1,STONE)
Block(3,3,0,STONE)
Block(3,3,1,STONE)
Block(3,4,-10,STONE)
Block(3,4,-9,STONE)
Block(3,4,-8,STONE)
Block(3,4,-7,STONE)
Block(3,4,-6,STONE)
Block(3,4,-5,STONE)
Block(3,4,-4,STONE)
Block(3,4,-3,STONE)
Block(3,4,-2,STONE)
Block(3,4,-1,STONE)
Block(3,4,0,STONE)
Block(3,4,1,STONE)
Block(3,4,2,STONE)
Block(3,4,3,STONE)
Block(3,4,4,STONE)
Block(3,5,-10,GRASS)
Block(3,5,-9,GRASS)
Block(3,5,-8,GRASS)
Block(3,5,-7,GRASS)
Block(3,5,-6,GRASS)
Block(3,5,-5,GRASS)
Block(3,5,-4,GRASS)
Block(3,5,-3,GRASS)
Block(3,5,-2,GRASS)
Block(3,5,-1,GRASS)
Block(3,5,0,GRASS)
Block(3,5,1,STONE)
Block(3,5,2,STONE)
Block(3,5,3,STONE)
Block(3,5,4,STONE)
Block(3,6,1,GRASS)
Block(3,6,2,GRASS)
Block(3,6,3,GRASS)
Block(3,6,4,GRASS)
Block(4,1,0,STONE)
Block(4,2,-3,STONE)
Block(4,2,-2,STONE)
Block(4,2,-1,STONE)
Block(4,2,0,STONE)
Block(4,3,-9,STONE)
Block(4,3,-8,STONE)
Block(4,3,-7,STONE)
Block(4,3,-6,STONE)
Block(4,3,-5,STONE)
Block(4,3,-4,STONE)
Block(4,3,-3,STONE)
Block(4,3,-2,STONE)
Block(4,3,-1,STONE)
Block(4,3,0,STONE)
Block(4,3,1,STONE)
Block(4,3,2,STONE)
Block(4,3,3,STONE)
Block(4,4,-12,STONE)
Block(4,4,-11,STONE)
Block(4,4,-10,STONE)
Block(4,4,-9,STONE)
Block(4,4,-8,STONE)
Block(4,4,-7,STONE)
Block(4,4,-6,STONE)
Block(4,4,-5,STONE)
Block(4,4,-4,STONE)
Block(4,4,-3,STONE)
Block(4,4,-2,STONE)
Block(4,4,-1,STONE)
Block(4,4,0,STONE)
Block(4,4,1,STONE)
Block(4,4,2,STONE)
Block(4,4,3,STONE)
Block(4,4,4,STONE)
Block(4,4,5,STONE)
Block(4,4,6,STONE)
Block(4,5,-12,GRASS)
Block(4,5,-11,GRASS)
Block(4,5,-10,GRASS)
Block(4,5,-9,GRASS)
Block(4,5,-8,GRASS)
Block(4,5,-7,GRASS)
Block(4,5,-6,GRASS)
Block(4,5,-5,GRASS)
Block(4,5,-4,GRASS)
Block(4,5,-3,STONE)
Block(4,5,-2,STONE)
Block(4,5,-1,STONE)
Block(4,5,0,STONE)
Block(4,5,1,STONE)
Block(4,5,2,STONE)
Block(4,5,3,STONE)
Block(4,5,4,STONE)
Block(4,5,5,STONE)
Block(4,5,6,STONE)
Block(4,6,-3,GRASS)
Block(4,6,-2,GRASS)
Block(4,6,-1,GRASS)
Block(4,6,0,GRASS)
Block(4,6,1,GRASS)
Block(4,6,2,GRASS)
Block(4,6,3,DIRT)
Block(4,6,4,STONE)
Block(4,6,5,STONE)
Block(4,6,6,STONE)
Block(4,7,3,GRASS)
Block(4,7,4,GRASS)
Block(4,7,5,DIRT)
Block(4,7,6,DIRT)
Block(4,8,5,GRASS)
Block(4,8,6,GRASS)
Block(5,0,0,STONE)
Block(5,1,-1,STONE)
Block(5,1,0,STONE)
Block(5,1,1,STONE)
Block(5,2,-6,STONE)
Block(5,2,-5,STONE)
Block(5,2,-4,STONE)
Block(5,2,-3,STONE)
Block(5,2,-2,STONE)
Block(5,2,-1,STONE)
Block(5,2,0,STONE)
Block(5,2,1,STONE)
Block(5,2,2,STONE)
Block(5,3,-11,STONE)
Block(5,3,-10,STONE)
Block(5,3,-9,STONE)
Block(5,3,-8,STONE)
Block(5,3,-7,STONE)
Block(5,3,-6,STONE)
Block(5,3,-5,STONE)
Block(5,3,-4,STONE)
Block(5,3,-3,STONE)
Block(5,3,-2,STONE)
Block(5,3,-1,STONE)
Block(5,3,0,STONE)
Block(5,3,1,STONE)
Block(5,3,2,STONE)
Block(5,3,3,STONE)
Block(5,3,4,STONE)
Block(5,4,-13,STONE)
Block(5,4,-12,STONE)
Block(5,4,-11,STONE)
Block(5,4,-10,STONE)
Block(5,4,-9,STONE)
Block(5,4,-8,STONE)
Block(5,4,-7,STONE)
Block(5,4,-6,STONE)
Block(5,4,-5,STONE)
Block(5,4,-4,STONE)
Block(5,4,-3,STONE)
Block(5,4,-2,STONE)
Block(5,4,-1,STONE)
Block(5,4,0,STONE)
Block(5,4,1,STONE)
Block(5,4,2,STONE)
Block(5,4,3,STONE)
Block(5,4,4,STONE)
Block(5,4,5,STONE)
Block(5,4,6,STONE)
Block(5,5,-13,GRASS)
Block(5,5,-12,GRASS)
Block(5,5,-11,GRASS)
Block(5,5,-10,GRASS)
Block(5,5,-9,GRASS)
Block(5,5,-8,GRASS)
Block(5,5,-7,GRASS)
Block(5,5,-6,GRASS)
Block(5,5,-5,STONE)
Block(5,5,-4,STONE)
Block(5,5,-3,STONE)
Block(5,5,-2,STONE)
Block(5,5,-1,STONE)
Block(5,5,0,STONE)
Block(5,5,1,STONE)
Block(5,5,2,STONE)
Block(5,5,3,STONE)
Block(5,5,4,STONE)
Block(5,5,5,STONE)
Block(5,5,6,STONE)
Block(5,6,-5,GRASS)
Block(5,6,-4,GRASS)
Block(5,6,-3,GRASS)
Block(5,6,-2,GRASS)
Block(5,6,-1,GRASS)
Block(5,6,0,GRASS)
Block(5,6,1,GRASS)
Block(5,6,2,DIRT)
Block(5,6,3,STONE)
Block(5,6,4,STONE)
Block(5,6,5,STONE)
Block(5,6,6,STONE)
Block(5,7,2,GRASS)
Block(5,7,3,GRASS)
Block(5,7,4,DIRT)
Block(5,7,5,DIRT)
Block(5,7,6,DIRT)
Block(5,8,4,GRASS)
Block(5,8,5,GRASS)
Block(5,8,6,GRASS)
Block(6,1,0,STONE)
Block(6,2,-3,STONE)
Block(6,2,-2,STONE)
Block(6,2,-1,STONE)
Block(6,2,0,STONE)
Block(6,2,1,STONE)
Block(6,3,-8,STONE)
Block(6,3,-7,STONE)
Block(6,3,-6,STONE)
Block(6,3,-5,STONE)
Block(6,3,-4,STONE)
Block(6,3,-3,STONE)
Block(6,3,-2,STONE)
Block(6,3,-1,STONE)
Block(6,3,0,STONE)
Block(6,3,1,STONE)
Block(6,3,2,STONE)
Block(6,3,3,STONE)
Block(6,4,-14,STONE)
Block(6,4,-13,STONE)
Block(6,4,-12,STONE)
Block(6,4,-11,STONE)
Block(6,4,-10,STONE)
Block(6,4,-9,STONE)
Block(6,4,-8,STONE)
Block(6,4,-7,STONE)
Block(6,4,-6,STONE)
Block(6,4,-5,STONE)
Block(6,4,-4,STONE)
Block(6,4,-3,STONE)
Block(6,4,-2,STONE)
Block(6,4,-1,STONE)
Block(6,4,0,STONE)
Block(6,4,1,STONE)
Block(6,4,2,STONE)
Block(6,4,3,STONE)
Block(6,4,4,STONE)
Block(6,4,5,STONE)
Block(6,5,-14,GRASS)
Block(6,5,-13,GRASS)
Block(6,5,-12,GRASS)
Block(6,5,-11,GRASS)
Block(6,5,-10,GRASS)
Block(6,5,-9,GRASS)
Block(6,5,-8,GRASS)
Block(6,5,-7,GRASS)
Block(6,5,-6,GRASS)
Block(6,5,-5,GRASS)
Block(6,5,-4,STONE)
Block(6,5,-3,STONE)
Block(6,5,-2,STONE)
Block(6,5,-1,STONE)
Block(6,5,0,STONE)
Block(6,5,1,STONE)
Block(6,5,2,STONE)
Block(6,5,3,STONE)
Block(6,5,4,STONE)
Block(6,5,5,STONE)
Block(6,6,-4,GRASS)
Block(6,6,-3,GRASS)
Block(6,6,-2,GRASS)
Block(6,6,-1,GRASS)
Block(6,6,0,GRASS)
Block(6,6,1,DIRT)
Block(6,6,2,STONE)
Block(6,6,3,STONE)
Block(6,6,4,STONE)
Block(6,6,5,STONE)
Block(6,7,1,GRASS)
Block(6,7,2,GRASS)
Block(6,7,3,GRASS)
Block(6,7,4,DIRT)
Block(6,7,5,DIRT)
Block(6,8,4,GRASS)
Block(6,8,5,GRASS)
Block(7,3,-4,STONE)
Block(7,3,-3,STONE)
Block(7,3,-2,STONE)
Block(7,3,-1,STONE)
Block(7,3,0,STONE)
Block(7,3,1,STONE)
Block(7,4,-9,STONE)
Block(7,4,-8,STONE)
Block(7,4,-7,STONE)
Block(7,4,-6,STONE)
Block(7,4,-5,STONE)
Block(7,4,-4,STONE)
Block(7,4,-3,STONE)
Block(7,4,-2,STONE)
Block(7,4,-1,STONE)
Block(7,4,0,STONE)
Block(7,4,1,STONE)
Block(7,4,2,STONE)
Block(7,4,3,STONE)
Block(7,5,-9,GRASS)
Block(7,5,-8,GRASS)
Block(7,5,-7,GRASS)
Block(7,5,-6,GRASS)
Block(7,5,-5,GRASS)
Block(7,5,-4,GRASS)
Block(7,5,-3,GRASS)
Block(7,5,-2,GRASS)
Block(7,5,-1,STONE)
Block(7,5,0,STONE)
Block(7,5,1,STONE)
Block(7,5,2,STONE)
Block(7,5,3,STONE)
Block(7,5,4,STONE)
Block(7,6,-1,GRASS)
Block(7,6,0,GRASS)
Block(7,6,1,GRASS)
Block(7,6,2,GRASS)
Block(7,6,3,DIRT)
Block(7,6,4,GRASS)
Block(7,7,3,GRASS)
Block(8,4,-5,STONE)
Block(8,4,-4,STONE)
Block(8,4,-3,STONE)
Block(8,4,-2,STONE)
Block(8,4,-1,STONE)
Block(8,4,0,STONE)
Block(8,4,1,STONE)
Block(8,5,-5,GRASS)
Block(8,5,-4,GRASS)
Block(8,5,-3,GRASS)
Block(8,5,-2,GRASS)
Block(8,5,-1,GRASS)
Block(8,5,0,GRASS)
Block(8,5,1,DIRT)
Block(8,6,1,GRASS)
Block(8,9,-15,WOOL:1)

#######################################################################
# +-----------------------------------------------------------------+ #
# |                            BO3 checks                           | #
# +-----------------------------------------------------------------+ #
#######################################################################

# Require a condition at a certain location in order for the BO3 to be spawned.
# BlockCheck(x,y,z,BlockName[,BlockName[,...]]) - one of the blocks must be at the location
# BlockCheckNot(x,y,z,BlockName[,BlockName[,...]]) - all the blocks must not be at the location
# LightCheck(x,y,z,minLightLevel,maxLightLevel) - light must be between min and max (inclusive)

# You can use "Solid" as a BlockName for matching all solid blocks or "All" to match all blocks that aren't air.

# Examples:
#   BlockCheck(0,-1,0,GRASS,DIRT)  Require grass or dirt just below the object
#   BlockCheck(0,-1,0,Solid)       Require any solid block just below the object
#   BlockCheck(0,-1,0,WOOL)        Require any type of wool just below the object
#   BlockCheck(0,-1,0,WOOL:0)      Require white wool just below the object
#   BlockCheckNot(0,-1,0,WOOL:0)   Require that there is no white wool below the object
#   LightCheck(0,0,0,0,1)          Require almost complete darkness just below the object

#######################################################################
# +-----------------------------------------------------------------+ #
# |                             Branches                            | #
# +-----------------------------------------------------------------+ #
#######################################################################

# Branches are objects that will spawn when this object spawns when it is used in
# the CustomStructure resource. Branches can also have branches, making complex
# structures possible. See the wiki for more details.

# Regular Branches spawn each branch with an independent chance of spawning.
# Branch(x,y,z,branchName,rotation,chance[,anotherBranchName,rotation,chance[,...]][IndividualChance])
# branchName - name of the object to spawn.
# rotation - NORTH, SOUTH, EAST or WEST.
# IndividualChance - The chance each branch has to spawn, assumed to be 100 when left blank

# Weighted Branches spawn branches with a dependent chance of spawning.
# WeightedBranch(x,y,z,branchName,rotation,chance[,anotherBranchName,rotation,chance[,...]][MaxChanceOutOf])
# MaxChanceOutOf - The chance all branches have to spawn out of, assumed to be 100 when left blank
